Workbook

Sheet Base_Cobranzas
A1: Proyecto | B1: Etapa | C1: Tipo_Construccion_1 | D1: Nombre_Tipo_Construccion_1 | E1: TipoInmueble_1 | F1: NroInmueble_1 | G1: AreaTechada_1 | H1: AreaLibre_1 | I1: PrecioLista_1 | J1: PrecioVenta_1 | K1: Tipo_Construccion_2 | L1: Nombre_Tipo_Construccion_2 | M1: TipoInmueble_2 | N1: NroInmueble_2 | O1: AreaTechada_2 | P1: AreaLibre_2 | Q1: PrecioLista_2 | R1: PrecioVenta_2 | S1: Tipo_Construccion_3 | T1: Nombre_Tipo_Construccion_3 | U1: TipoInmueble_3 | V1: NroInmueble_3 | W1: AreaTechada_3 | X1: AreaLibre_3 | Y1: PrecioLista_3 | Z1: PrecioVenta_3 | AA1: Tipo_Construccion_4 | AB1: Nombre_Tipo_Construccion_4 | AC1: TipoInmueble_4 | AD1: NroInmueble_4 | AE1: AreaTechada_4 | AF1: AreaLibre_4 | AG1: PrecioLista_4 | AH1: PrecioVenta_4 | AI1: Nombres_Titular | AJ1: NroDocumento | AK1: Direccion | AL1: TelefonoCasa | AM1: TelefonoCelular | AN1: CorreoElectronico | AO1: Provincia | AP1: Distrito | AQ1: Fecha_Programada | AR1: FechaPago | AS1: Tipo_Cuota | AT1: Nro_Cuota | AU1: Capital | AV1: Intereses | AW1: GastosAdministrativos | AX1: Monto_Cuota | AY1: Monto_Cuota_Pagado | AZ1: SaldoPorPagarCuota | BA1: MontoMora | BB1: TipoFinanciamiento | BC1: Entidad_Financiera | BD1: Nro_Cuenta | BE1: Medio_Pago | BF1: Nro_Documento | BG1: Nro_Operacion | BH1: Verificado | BI1: OrigenFondo | BJ1: TipoCambio | BK1: Estado | BL1: Estado_Letra | BM1: Ubicación_Letra | BN1: Casuistica_Cuota | BO1: Accio_Cuota | BP1: FechaPromesa | BQ1: ValorCompromiso | BR1: Porcentaje | BS1: Comentario_Cuota | BT1: Fecha_Modificiacion_Seguimiento | BU1: Usuario_Modificiacion_Seguimiento | BV1: Doc_Adjunto | BW1: FechaOperacionComercial | BX1: Asesor_Comercial | BY1: Asesor_Banco | BZ1: Correlativo | CA1: Fecha_Registro_Pago_Cargado | CB1: ComisionPago | CC1: IdCotizacion | CD1: Doc_Contable | CE1: Monto_EstadoCuenta | CF1: Archivo_Origen | CG1: Anio_Descarga | CH1: Fecha_Inicio_Reporte | CI1: Fecha_Fin_Reporte
A2: RESIDENCIAL PRADA | B2: Etapa 1 | C2: Edificio | D2: A | E2: Departamento | F2: 103 | G2: 60.94 | H2: 30.59 | I2: 520400 | J2: 520400 | AI2: Ayleen Katia Messarina Rios | AJ2: 70512701 | AK2: Departamento 101 Urbanización Santa Rosa de Surco etapa 2 Mz D Lt 23 | AL2: 978722675 | AM2: 978722675 | AN2: ayleen30mr@gmail.com | AO2: LIMA | AP2: SANTIAGO DE SURCO | AQ2: 45578 | AR2: 45578 | AS2: SEPARACION | AT2: 1 | AU2: 3000 | AV2: 0 | AW2: 0 | AX2: 3000 | AY2: 3000 | AZ2: 0 | BA2: 0 | BB2: Crédito Hipotecario | BC2: Scotiabank Perú | BD2: 000-2768484 | BE2: TRANSFERENCIA BANCARIA | BG2: 01871075 | BH2: No | BJ2: 4 | BK2: CANCELADO | BV2: Si | BW2: 45663.588 | BX2: Kenny Salazar S | BZ2: 31 | CA2: 26/06/2026 17:22 | CB2: 0 | CF2: Cobranzas_2024.csv | CG2: 2024 | CH2: 01/01/2024 | CI2: 31/08/2031
A3: RESIDENCIAL PRADA | B3: Etapa 1 | C3: Edificio | D3: A | E3: Estacionamiento | F3: E 14 - D 11 | G3: 14.63 | H3: 2.37 | I3: 56300 | J3: 56300 | AI3: Ayleen Katia Messarina Rios | AJ3: 70512701 | AK3: Departamento 101 Urbanización Santa Rosa de Surco etapa 2 Mz D Lt 23 | AL3: 978722675 | AM3: 978722675 | AN3: ayleen30mr@gmail.com | AO3: LIMA | AP3: SANTIAGO DE SURCO | AQ3: 45628 | AR3: 45628 | AS3: SEPARACION | AT3: 1 | AU3: 3000 | AV3: 0 | AW3: 0 | AX3: 3000 | AY3: 3000 | AZ3: 0 | BA3: 0 | BB3: Crédito Directo | BC3: Scotiabank Perú | BD3: 000-2768484 | BE3: TRANSFERENCIA BANCARIA | BG3: 000001100000012 | BH3: No | BJ3: 4 | BK3: CANCELADO | BV3: Si | BW3: 45748.63 | BX3: Magaly Guevara Perez | BZ3: 56 | CA3: 28/06/2026 21:22 | CB3: 0 | CF3: Cobranzas_2024.csv | CG3: 2024 | CH3: 01/01/2024 | CI3: 31/08/2031
A4: RESIDENCIAL PRADA | B4: Etapa 1 | C4: Edificio | D4: A | E4: Estacionamiento | F4: E 14 - D 11 | G4: 14.63 | H4: 2.37 | I4: 56300 | J4: 56300 | AI4: Ayleen Katia Messarina Rios | AJ4: 70512701 | AK4: Departamento 101 Urbanización Santa Rosa de Surco etapa 2 Mz D Lt 23 | AL4: 978722675 | AM4: 978722675 | AN4: ayleen30mr@gmail.com | AO4: LIMA | AP4: SANTIAGO DE SURCO | AQ4: 45628 | AR4: 45628 | AS4: CUOTA INICIAL | AT4: 1 | AU4: 7000 | AV4: 0 | AW4: 0 | AX4: 7000 | AY4: 7000 | AZ4: 0 | BA4: 0 | BB4: Crédito Directo | BC4: Scotiabank Perú | BD4: 000-2768484 | BE4: TRANSFERENCIA BANCARIA | BG4: 000001100000012 | BH4: No | BJ4: 4 | BK4: CANCELADO | BV4: Si | BW4: 45748.63 | BX4: Magaly Guevara Perez | BZ4: 56 | CA4: 28/06/2026 21:22 | CB4: 0 | CF4: Cobranzas_2024.csv | CG4: 2024 | CH4: 01/01/2024 | CI4: 31/08/2031
A5: RESIDENCIAL PRADA | B5: Etapa 1 | C5: Edificio | D5: A | E5: Departamento | F5: 302 | G5: 55 | H5: 0 | I5: 435500 | J5: 435500 | AI5: Cristhiam Ortiz Angeles | AJ5: 45110882 | AK5: Av. Olavegoya 1879 departamento 301 | AL5: 992532732 | AM5: 992532732 | AN5: Cristhian4520@gmail.com | AO5: LIMA | AP5: JESUS MARIA | AQ5: 45473 | AR5: 45473 | AS5: SEPARACION | AT5: 1 | AU5: 3000 | AV5: 0 | AW5: 0 | AX5: 3000 | AY5: 3000 | AZ5: 0 | BA5: 0 | BB5: Crédito Hipotecario | BC5: Scotiabank Perú | BD5: 000-2768484 | BE5: TRANSFERENCIA BANCARIA | BF5: 45110882 | BG5: 01226077 | BH5: No | BI5: NO PRECISA | BJ5: 4 | BK5: CANCELADO | BV5: Si | BW5: 45499.613 | BX5: Kenny Salazar S | BZ5: 34 | CA5: 02/06/2026 15:34 | CB5: 0 | CF5: Cobranzas_2024.csv | CG5: 2024 | CH5: 01/01/2024 | CI5: 31/08/2031
A6: RESIDENCIAL PRADA | B6: Etapa 1 | C6: Edificio | D6: A | E6: Departamento | F6: 302 | G6: 55 | H6: 0 | I6: 435500 | J6: 435500 | AI6: Cristhiam Ortiz Angeles | AJ6: 45110882 | AK6: Av. Olavegoya 1879 departamento 301 | AL6: 992532732 | AM6: 992532732 | AN6: Cristhian4520@gmail.com | AO6: LIMA | AP6: JESUS MARIA | AQ6: 45499 | AR6: 45499 | AS6: CUOTA INICIAL | AT6: 1 | AU6: 20000 | AV6: 0 | AW6: 0 | AX6: 20000 | AY6: 20000 | AZ6: 0 | BA6: 0 | BB6: Crédito Hipotecario | BC6: Scotiabank Perú | BD6: 000-2768484 | BE6: CHEQUE DE GERENCIA | BF6: 45110882 | BG6: 162515191002194000000022290 | BH6: Si | BI6: NO PRECISA | BJ6: 4 | BK6: CANCELADO | BV6: Si | BW6: 45499.613 | BX6: Kenny Salazar S | BZ6: 34 | CA6: 04/06/2026 14:01 | CB6: 0 | CF6: Cobranzas_2024.csv | CG6: 2024 | CH6: 01/01/2024 | CI6: 31/08/2031
A7: RESIDENCIAL PRADA | B7: Etapa 1 | C7: Edificio | D7: A | E7: Departamento | F7: 302 | G7: 55 | H7: 0 | I7: 435500 | J7: 435500 | AI7: Cristhiam Ortiz Angeles | AJ7: 45110882 | AK7: Av. Olavegoya 1879 departamento 301 | AL7: 992532732 | AM7: 992532732 | AN7: Cristhian4520@gmail.com | AO7: LIMA | AP7: JESUS MARIA | AQ7: 45534 | AR7: 45538 | AS7: CUOTA INICIAL | AT7: 2 | AU7: 8775 | AV7: 0 | AW7: 0 | AX7: 8775 | AY7: 8775 | AZ7: 0 | BA7: 0 | BB7: Crédito Hipotecario | BC7: Scotiabank Perú | BD7: 000-2768484 | BE7: TRANSFERENCIA BANCARIA | BG7: U26966 | BH7: No | BJ7: 4 | BK7: CANCELADO | BV7: Si | BW7: 45499.613 | BX7: Kenny Salazar S | BZ7: 34 | CA7: 07/07/2026 08:47 | CB7: 0 | CF7: Cobranzas_2024.csv | CG7: 2024 | CH7: 01/01/2024 | CI7: 31/08/2031
A8: RESIDENCIAL PRADA | B8: Etapa 1 | C8: Edificio | D8: A | E8: Departamento | F8: 302 | G8: 55 | H8: 0 | I8: 435500 | J8: 435500 | AI8: Cristhiam Ortiz Angeles | AJ8: 45110882 | AK8: Av. Olavegoya 1879 departamento 301 | AL8: 992532732 | AM8: 992532732 | AN8: Cristhian4520@gmail.com | AO8: LIMA | AP8: JESUS MARIA | AQ8: 45565 | AR8: 45538 | AS8: CUOTA INICIAL | AT8: 3 | AU8: 0 | AV8: 0 | AW8: 0 | AX8: 11775 | AY8: 1225 | AZ8: 0 | BA8: 0 | BB8: Crédito Hipotecario | BC8: Scotiabank Perú | BD8: 000-2768484 | BE8: TRANSFERENCIA BANCARIA | BG8: U26966 | BH8: No | BJ8: 4 | BK8: CANCELADO | BV8: Si | BW8: 45499.613 | BX8: Kenny Salazar S | BZ8: 34 | CA8: 07/07/2026 08:47 | CB8: 0 | CF8: Cobranzas_2024.csv | CG8: 2024 | CH8: 01/01/2024 | CI8: 31/08/2031
A9: RESIDENCIAL PRADA | B9: Etapa 1 | C9: Edificio | D9: A | E9: Departamento | F9: 302 | G9: 55 | H9: 0 | I9: 435500 | J9: 435500 | AI9: Cristhiam Ortiz Angeles | AJ9: 45110882 | AK9: Av. Olavegoya 1879 departamento 301 | AL9: 992532732 | AM9: 992532732 | AN9: Cristhian4520@gmail.com | AO9: LIMA | AP9: JESUS MARIA | AQ9: 45565 | AR9: 45569 | AS9: CUOTA INICIAL | AT9: 3 | AU9: 0 | AV9: 0 | AW9: 0 | AX9: 0 | AY9: 10000 | AZ9: 0 | BA9: 0 | BB9: Crédito Hipotecario | BC9: Scotiabank Perú | BD9: 000-2768484 | BE9: TRANSFERENCIA BANCARIA | BG9: U27618 | BH9: No | BJ9: 4 | BK9: CANCELADO | BV9: Si | BW9: 45499.613 | BX9: Kenny Salazar S | BZ9: 34 | CA9: 07/07/2026 08:52 | CB9: 0 | CF9: Cobranzas_2024.csv | CG9: 2024 | CH9: 01/01/2024 | CI9: 31/08/2031
A10: RESIDENCIAL PRADA | B10: Etapa 1 | C10: Edificio | D10: A | E10: Departamento | F10: 302 | G10: 55 | H10: 0 | I10: 435500 | J10: 435500 | AI10: Cristhiam Ortiz Angeles | AJ10: 45110882 | AK10: Av. Olavegoya 1879 departamento 301 | AL10: 992532732 | AM10: 992532732 | AN10: Cristhian4520@gmail.com | AO10: LIMA | AP10: JESUS MARIA | AQ10: 45565 | AR10: 45693 | AS10: CUOTA INICIAL | AT10: 3 | AU10: 11775 | AV10: 0 | AW10: 0 | AX10: 0 | AY10: 550 | AZ10: 0 | BA10: 0 | BB10: Crédito Hipotecario | BC10: Scotiabank Perú | BD10: 000-2768484 | BE10: TRANSFERENCIA BANCARIA | BG10: U28731 | BH10: No | BJ10: 4 | BK10: CANCELADO | BV10: Si | BW10: 45499.613 | BX10: Kenny Salazar S | BZ10: 34 | CA10: 07/07/2026 08:56 | CB10: 0 | CF10: Cobranzas_2024.csv | CG10: 2024 | CH10: 01/01/2024 | CI10: 31/08/2031
A11: RESIDENCIAL PRADA | B11: Etapa 1 | C11: Edificio | D11: A | E11: Departamento | F11: 302 | G11: 55 | H11: 0 | I11: 435500 | J11: 435500 | AI11: Cristhiam Ortiz Angeles | AJ11: 45110882 | AK11: Av. Olavegoya 1879 departamento 301 | AL11: 992532732 | AM11: 992532732 | AN11: Cristhian4520@gmail.com | AO11: LIMA | AP11: JESUS MARIA | AQ11: 45656 | AR11: 45693 | AS11: CUOTA INICIAL | AT11: 4 | AU11: 21000 | AV11: 0 | AW11: 0 | AX11: 21000 | AY11: 21000 | AZ11: 0 | BA11: 0 | BB11: Crédito Hipotecario | BC11: Scotiabank Perú | BD11: 000-2768484 | BE11: TRANSFERENCIA BANCARIA | BG11: U28731 | BH11: No | BJ11: 4 | BK11: CANCELADO | BV11: Si | BW11: 45499.613 | BX11: Kenny Salazar S | BZ11: 34 | CA11: 07/07/2026 08:56 | CB11: 0 | CF11: Cobranzas_2024.csv | CG11: 2024 | CH11: 01/01/2024 | CI11: 31/08/2031
A12: RESIDENCIAL BEYOND | B12: Etapa 1 | C12: Edificio | D12: A | E12: Departamento | F12: 505 | G12: 72 | H12: 0 | I12: 532100 | J12: 500000 | K12: Edificio | L12: A | M12: Estacionamiento | N12: E 05 | O12: 12 | P12: 0 | Q12: 45600 | R12: 45600 | S12: Edificio | T12: A | U12: Depósito | V12: D 05 | W12: 4.4 | X12: 0 | Y12: 15900 | Z12: 15900 | AI12: Dante Enrique Segura Florian | AJ12: 45587286 | AK12: 1845 San Andres Dr Pitsburg CA 94565 - San Francisco | AL12: 0 | AM12: +15103330517 | AN12: d.segura@uaa.edu | AQ12: 45368 | AR12: 45368 | AS12: SEPARACION | AT12: 1 | AU12: 3000 | AV12: 0 | AW12: 0 | AX12: 3000 | AY12: 3000 | AZ12: 0 | BA12: 0 | BB12: Crédito Directo | BC12: Banco de Credito del Perú | BD12: 194-7325779-0-65 | BE12: TRANSFERENCIA BANCARIA | BG12: 7844655595634 | BH12: No | BJ12: 4 | BK12: CANCELADO | BV12: Si | BW12: 45386.403 | BX12: Carla Michue M | BZ12: 35 | CA12: 25/05/2026 17:28 | CB12: 0 | CF12: Cobranzas_2024.csv | CG12: 2024 | CH12: 01/01/2024 | CI12: 31/08/2031
A13: RESIDENCIAL PRADA | B13: Etapa 1 | C13: Edificio | D13: A | E13: Departamento | F13: 703 | G13: 88.27 | H13: 0 | I13: 654000 | J13: 654000 | K13: Edificio | L13: A | M13: Estacionamiento | N13: E 06 - D 04 | O13: 15.9 | P13: 2.26 | Q13: 57500 | R13: 57500 | AI13: David Edgar Valencia Cordova | AJ13: 41844906 | AK13: P. Joven Año Nuevo Jr. Montero Rosas 860 | AL13: 991846561 | AM13: 991846561 | AN13: davico29@gmail.com | AO13: LIMA | AP13: COMAS | AQ13: 45655 | AR13: 45655 | AS13: SEPARACION | AT13: 1 | AU13: 3000 | AV13: 0 | AW13: 0 | AX13: 3000 | AY13: 3000 | AZ13: 0 | BA13: 0 | BB13: Crédito Hipotecario | BC13: Scotiabank Perú | BD13: 000-2768484 | BE13: TRANSFERENCIA BANCARIA | BF13: 41844906 | BG13: 00000082000000000 | BH13: No | BI13: NO PRECISA | BJ13: 4 | BK13: CANCELADO | BV13: Si | BW13: 45687.617 | BX13: Carla Michue M | BZ13: 38 | CA13: 02/06/2026 18:05 | CB13: 0 | CF13: Cobranzas_2024.csv | CG13: 2024 | CH13: 01/01/2024 | CI13: 31/08/2031
A14: RESIDENCIAL PRADA | B14: Etapa 1 | C14: Edificio | D14: A | E14: Departamento | F14: 205 | G14: 68.72 | H14: 0 | I14: 490000 | J14: 490000 | AI14: Elizabeth Rocio Urbina Ñañez | AJ14: 71404863 | AK14: Av. Arequipa 2651 | AM14: 943921218 | AN14: elizabethurbina9624@gmail.com | AO14: LIMA | AP14: LINCE | AQ14: 45620 | AR14: 45620 | AS14: SEPARACION | AT14: 1 | AU14: 2000 | AV14: 0 | AW14: 0 | AX14: 2000 | AY14: 2000 | AZ14: 0 | BA14: 0 | BB14: Crédito Hipotecario | BC14: Scotiabank Perú | BD14: 000-2768484 | BE14: TRANSFERENCIA BANCARIA | BG14: FD893378 | BH14: No | BJ14: 4 | BK14: CANCELADO | BV14: Si | BW14: 45750.733 | BX14: Carla Michue M | BZ14: 5 | CA14: 29/06/2026 21:44 | CB14: 0 | CF14: Cobranzas_2024.csv | CG14: 2024 | CH14: 01/01/2024 | CI14: 31/08/2031
A15: RESIDENCIAL PRADA | B15: Etapa 1 | C15: Edificio | D15: A | E15: Departamento | F15: 101 | G15: 80.58 | H15: 18.9 | I15: 637000 | J15: 637000 | AI15: Elmo Calatayud Chumbes | AJ15: 15580131 | AK15: Avenida Tomas Valles 1530 Block 14 departamento 204 | AL15: 955600933 | AM15: 955600933 | AN15: ec.calatayud@gmail.com | AO15: LIMA | AP15: LOS OLIVOS | AQ15: 45595 | AR15: 45595 | AS15: SEPARACION | AT15: 1 | AU15: 3000 | AV15: 0 | AW15: 0 | AX15: 3000 | AY15: 3000 | AZ15: 0 | BA15: 0 | BB15: Crédito Hipotecario | BC15: Scotiabank Perú | BD15: 000-2768484 | BE15: TRANSFERENCIA BANCARIA | BG15: 04797111 | BH15: No | BJ15: 4 | BK15: CANCELADO | BV15: Si | BW15: 45626.65 | BX15: Carla Michue M | BZ15: 25 | CA15: 26/06/2026 14:52 | CB15: 0 | CF15: Cobranzas_2024.csv | CG15: 2024 | CH15: 01/01/2024 | CI15: 31/08/2031
A16: RESIDENCIAL PRADA | B16: Etapa 1 | C16: Edificio | D16: A | E16: Departamento | F16: 101 | G16: 80.58 | H16: 18.9 | I16: 637000 | J16: 637000 | AI16: Elmo Calatayud Chumbes | AJ16: 15580131 | AK16: Avenida Tomas Valles 1530 Block 14 departamento 204 | AL16: 955600933 | AM16: 955600933 | AN16: ec.calatayud@gmail.com | AO16: LIMA | AP16: LOS OLIVOS | AQ16: 45626 | AR16: 45626 | AS16: CUOTA INICIAL | AT16: 1 | AU16: 27000 | AV16: 0 | AW16: 0 | AX16: 27000 | AY16: 27000 | AZ16: 0 | BA16: 0 | BB16: Crédito Hipotecario | BC16: Scotiabank Perú | BD16: 000-2768484 | BE16: TRANSFERENCIA BANCARIA | BG16: 78446555266223 | BH16: No | BJ16: 4 | BK16: CANCELADO | BV16: Si | BW16: 45626.65 | BX16: Carla Michue M | BZ16: 25 | CA16: 26/06/2026 14:53 | CB16: 0 | CF16: Cobranzas_2024.csv | CG16: 2024 | CH16: 01/01/2024 | CI16: 31/08/2031
A17: RESIDENCIAL PRADA | B17: Etapa 1 | C17: Edificio | D17: A | E17: Departamento | F17: 101 | G17: 80.58 | H17: 18.9 | I17: 637000 | J17: 637000 | AI17: Elmo Calatayud Chumbes | AJ17: 15580131 | AK17: Avenida Tomas Valles 1530 Block 14 departamento 204 | AL17: 955600933 | AM17: 955600933 | AN17: ec.calatayud@gmail.com | AO17: LIMA | AP17: LOS OLIVOS | AQ17: 45626 | AR17: 45626 | AS17: CUOTA INICIAL | AT17: 2 | AU17: 3000 | AV17: 0 | AW17: 0 | AX17: 3000 | AY17: 3000 | AZ17: 0 | BA17: 0 | BB17: Crédito Hipotecario | BC17: Scotiabank Perú | BD17: 000-2768484 | BE17: TRANSFERENCIA BANCARIA | BG17: 7844655544194 | BH17: No | BJ17: 4 | BK17: CANCELADO | BV17: Si | BW17: 45626.65 | BX17: Carla Michue M | BZ17: 25 | CA17: 26/06/2026 14:53 | CB17: 0 | CF17: Cobranzas_2024.csv | CG17: 2024 | CH17: 01/01/2024 | CI17: 31/08/2031
A18: RESIDENCIAL PRADA | B18: Etapa 1 | C18: Edificio | D18: A | E18: Departamento | F18: 101 | G18: 80.58 | H18: 18.9 | I18: 637000 | J18: 637000 | AI18: Elmo Calatayud Chumbes | AJ18: 15580131 | AK18: Avenida Tomas Valles 1530 Block 14 departamento 204 | AL18: 955600933 | AM18: 955600933 | AN18: ec.calatayud@gmail.com | AO18: LIMA | AP18: LOS OLIVOS | AQ18: 45656 | AR18: 45656 | AS18: CUOTA INICIAL | AT18: 3 | AU18: 0 | AV18: 0 | AW18: 0 | AX18: 30700 | AY18: 30000 | AZ18: 0 | BA18: 0 | BB18: Crédito Hipotecario | BC18: Scotiabank Perú | BD18: 000-2768484 | BE18: TRANSFERENCIA BANCARIA | BG18: 7844655610530 | BH18: No | BJ18: 4 | BK18: CANCELADO | BV18: Si | BW18: 45626.65 | BX18: Carla Michue M | BZ18: 25 | CA18: 26/06/2026 14:55 | CB18: 0 | CF18: Cobranzas_2024.csv | CG18: 2024 | CH18: 01/01/2024 | CI18: 31/08/2031
A19: RESIDENCIAL PRADA | B19: Etapa 1 | C19: Edificio | D19: A | E19: Departamento | F19: 101 | G19: 80.58 | H19: 18.9 | I19: 637000 | J19: 637000 | AI19: Elmo Calatayud Chumbes | AJ19: 15580131 | AK19: Avenida Tomas Valles 1530 Block 14 departamento 204 | AL19: 955600933 | AM19: 955600933 | AN19: ec.calatayud@gmail.com | AO19: LIMA | AP19: LOS OLIVOS | AQ19: 45656 | AR19: 45656 | AS19: CUOTA INICIAL | AT19: 3 | AU19: 30700 | AV19: 0 | AW19: 0 | AX19: 0 | AY19: 700 | AZ19: 0 | BA19: 0 | BB19: Crédito Hipotecario | BC19: Scotiabank Perú | BD19: 000-2768484 | BE19: TRANSFERENCIA BANCARIA | BG19: 7844655610860 | BH19: No | BJ19: 4 | BK19: CANCELADO | BV19: Si | BW19: 45626.65 | BX19: Carla Michue M | BZ19: 25 | CA19: 26/06/2026 14:56 | CB19: 0 | CF19: Cobranzas_2024.csv | CG19: 2024 | CH19: 01/01/2024 | CI19: 31/08/2031
A20: RESIDENCIAL PRADA | B20: Etapa 1 | C20: Edificio | D20: A | E20: Departamento | F20: 203 | G20: 88.27 | H20: 0 | I20: 654000 | J20: 654000 | K20: Edificio | L20: A | M20: Estacionamiento | N20: E 12 - D 09 | O20: 13 | P20: 3.89 | Q20: 56300 | R20: 56300 | AI20: Gilberto Videla Flores | AJ20: 06571347 | AK20: Mz D Lt 7 Urb. La Estrella | AM20: 969742622 | AN20: gvidelaf@gmail.com | AO20: LIMA | AP20: LOS OLIVOS | AQ20: 45535 | AR20: 45535 | AS20: SEPARACION | AT20: 1 | AU20: 3000 | AV20: 0 | AW20: 0 | AX20: 3000 | AY20: 3000 | AZ20: 0 | BA20: 0 | BB20: Crédito Directo | BC20: Scotiabank Perú | BD20: 000-2768484 | BE20: POS VISA | BF20: 06571347 | BG20: 0059 | BH20: No | BI20: NO PRECISA | BJ20: 1 | BK20: CANCELADO | BV20: Si | BW20: 45539.381 | BX20: Carla Michue M | BZ20: 24 | CA20: 29/05/2026 12:21 | CB20: 0 | CF20: Cobranzas_2024.csv | CG20: 2024 | CH20: 01/01/2024 | CI20: 31/08/2031
A21: RESIDENCIAL PRADA | B21: Etapa 1 | C21: Edificio | D21: A | E21: Departamento | F21: 203 | G21: 88.27 | H21: 0 | I21: 654000 | J21: 654000 | K21: Edificio | L21: A | M21: Estacionamiento | N21: E 12 - D 09 | O21: 13 | P21: 3.89 | Q21: 56300 | R21: 56300 | AI21: Gilberto Videla Flores | AJ21: 06571347 | AK21: Mz D Lt 7 Urb. La Estrella | AM21: 969742622 | AN21: gvidelaf@gmail.com | AO21: LIMA | AP21: LOS OLIVOS | AQ21: 45539 | AR21: 45539 | AS21: CUOTA INICIAL | AT21: 2 | AU21: 281120 | AV21: 0 | AW21: 0 | AX21: 281120 | AY21: 281120 | AZ21: 0 | BA21: 0 | BB21: Crédito Directo | BC21: Scotiabank Perú | BD21: 000-2768484 | BE21: TRANSFERENCIA BANCARIA | BG21: 0953413 | BH21: No | BJ21: 4 | BK21: CANCELADO | BV21: Si | BW21: 45539.381 | BX21: Carla Michue M | BZ21: 24 | CA21: 30/06/2026 16:33 | CB21: 0 | CF21: Cobranzas_2024.csv | CG21: 2024 | CH21: 01/01/2024 | CI21: 31/08/2031
A22: RESIDENCIAL PRADA | B22: Etapa 1 | C22: Edificio | D22: A | E22: Departamento | F22: 203 | G22: 88.27 | H22: 0 | I22: 654000 | J22: 654000 | K22: Edificio | L22: A | M22: Estacionamiento | N22: E 12 - D 09 | O22: 13 | P22: 3.89 | Q22: 56300 | R22: 56300 | AI22: Gilberto Videla Flores | AJ22: 06571347 | AK22: Mz D Lt 7 Urb. La Estrella | AM22: 969742622 | AN22: gvidelaf@gmail.com | AO22: LIMA | AP22: LOS OLIVOS | AQ22: 45559 | AR22: 45559 | AS22: SALDO FINANCIAR | AT22: 3 | AU22: 248605 | AV22: 0 | AW22: 0 | AX22: 248605 | AY22: 248605 | AZ22: 0 | BA22: 0 | BB22: Crédito Directo | BC22: Scotiabank Perú | BD22: 000-2768484 | BE22: TRANSFERENCIA BANCARIA | BG22: 0036913 | BH22: No | BJ22: 4 | BK22: CANCELADO | BV22: Si | BW22: 45539.381 | BX22: Carla Michue M | BZ22: 24 | CA22: 30/06/2026 16:48 | CB22: 0 | CF22: Cobranzas_2024.csv | CG22: 2024 | CH22: 01/01/2024 | CI22: 31/08/2031
A23: RESIDENCIAL PRADA | B23: Etapa 1 | C23: Edificio | D23: A | E23: Departamento | F23: 104 | G23: 68.52 | H23: 31.7 | I23: 609100 | J23: 609100 | K23: Edificio | L23: A | M23: Estacionamiento | N23: E 26 - D 20 | O23: 14.6 | P23: 3.89 | Q23: 64600 | R23: 64600 | AI23: Gilda Victoria Sampi González | AJ23: 43636501 | AK23: Av. Brasil 863 departamento 702-A | AL23: 966422784 | AM23: 966422784 | AN23: victoria.sampi@gmail.com | AO23: LIMA | AP23: JESUS MARIA | AQ23: 45494 | AR23: 45494 | AS23: SEPARACION | AT23: 1 | AU23: 3000 | AV23: 0 | AW23: 0 | AX23: 3000 | AY23: 3000 | AZ23: 0 | BA23: 0 | BB23: Crédito Hipotecario | BC23: Scotiabank Perú | BD23: 000-2768484 | BE23: TRANSFERENCIA BANCARIA | BF23: 43636501 | BG23: 00998929 | BH23: No | BI23: NO PRECISA | BJ23: 4 | BK23: CANCELADO | BV23: Si | BW23: 45537.593 | BX23: Kenny Salazar S | BZ23: 32 | CA23: 02/06/2026 14:50 | CB23: 0 | CF23: Cobranzas_2024.csv | CG23: 2024 | CH23: 01/01/2024 | CI23: 31/08/2031
A24: RESIDENCIAL PRADA | B24: Etapa 1 | C24: Edificio | D24: A | E24: Departamento | F24: 104 | G24: 68.52 | H24: 31.7 | I24: 609100 | J24: 609100 | K24: Edificio | L24: A | M24: Estacionamiento | N24: E 26 - D 20 | O24: 14.6 | P24: 3.89 | Q24: 64600 | R24: 64600 | AI24: Gilda Victoria Sampi González | AJ24: 43636501 | AK24: Av. Brasil 863 departamento 702-A | AL24: 966422784 | AM24: 966422784 | AN24: victoria.sampi@gmail.com | AO24: LIMA | AP24: JESUS MARIA | AQ24: 45537 | AR24: 45537 | AS24: CUOTA INICIAL | AT24: 1 | AU24: 134740 | AV24: 0 | AW24: 0 | AX24: 134740 | AY24: 134740 | AZ24: 0 | BA24: 0 | BB24: Crédito Hipotecario | BC24: Scotiabank Perú | BD24: 000-2768484 | BE24: TRANSFERENCIA BANCARIA | BF24: 43636501 | BG24: 009107870 | BH24: No | BI24: NO PRECISA | BJ24: 4 | BK24: CANCELADO | BV24: Si | BW24: 45537.593 | BX24: Kenny Salazar S | BZ24: 32 | CA24: 04/06/2026 09:52 | CB24: 0 | CF24: Cobranzas_2024.csv | CG24: 2024 | CH24: 01/01/2024 | CI24: 31/08/2031
A25: RESIDENCIAL PRADA | B25: Etapa 1 | C25: Edificio | D25: A | E25: Departamento | F25: 605 | G25: 68.72 | H25: 0 | I25: 501000 | J25: 501000 | K25: Edificio | L25: A | M25: Estacionamiento | N25: E 07 - D 05 | O25: 15.4 | P25: 2.26 | Q25: 57300 | R25: 57300 | AI25: Jose Humberto Pehovaz Diez | AJ25: 49073756 | AK25: - | AM25: 952256518 | AN25: josehp99@gmail.com | AO25: LIMA | AP25: MAGDALENA DEL MAR | AQ25: 45338 | AR25: 45698 | AS25: SEPARACION | AT25: 1 | AU25: 3000 | AV25: 0 | AW25: 0 | AX25: 3000 | AY25: 3000 | AZ25: 0 | BA25: 0 | BB25: Crédito Hipotecario | BC25: Scotiabank Perú | BD25: 000-2768484 | BE25: TRANSFERENCIA BANCARIA | BF25: 49073756 | BG25: 7844655534521 | BH25: No | BI25: NO PRECISA | BJ25: 1 | BK25: CANCELADO | BV25: Si | BW25: 45709.697 | BX25: Carla Michue M | BZ25: 10 | CA25: 29/05/2026 12:21 | CB25: 0 | CF25: Cobranzas_2024.csv | CG25: 2024 | CH25: 01/01/2024 | CI25: 31/08/2031
A26: RESIDENCIAL PRADA | B26: Etapa 1 | C26: Edificio | D26: A | E26: Departamento | F26: 201 | G26: 84 | H26: 0 | I26: 622500 | J26: 622500 | AI26: Joseluis Gaspar Zapata Flores | AJ26: 46730672 | AK26: Jr. Los Clavles 141 P. J El Progreso 1er Sector | AM26: 948041027 | AN26: jlzapata91@gmail.com | AO26: LIMA | AP26: CARABAYLLO | AQ26: 45479 | AR26: 45479 | AS26: CUOTA INICIAL | AT26: 1 | AU26: 3000 | AV26: 0 | AW26: 0 | AX26: 3000 | AY26: 3000 | AZ26: 0 | BA26: 0 | BB26: Ahorro | BC26: Scotiabank Perú | BD26: 000-2768484 | BE26: TRANSFERENCIA BANCARIA | BG26: 03343387 | BH26: Si | BJ26: 4 | BK26: CANCELADO | BV26: Si | BW26: 45488.655 | BX26: Carla Michue M | BZ26: 6 | CA26: 29/06/2026 01:05 | CB26: 0 | CF26: Cobranzas_2024.csv | CG26: 2024 | CH26: 01/01/2024 | CI26: 31/08/2031
A27: RESIDENCIAL PRADA | B27: Etapa 1 | C27: Edificio | D27: A | E27: Departamento | F27: 201 | G27: 84 | H27: 0 | I27: 622500 | J27: 622500 | AI27: Joseluis Gaspar Zapata Flores | AJ27: 46730672 | AK27: Jr. Los Clavles 141 P. J El Progreso 1er Sector | AM27: 948041027 | AN27: jlzapata91@gmail.com | AO27: LIMA | AP27: CARABAYLLO | AQ27: 45488 | AR27: 45488 | AS27: CUOTA INICIAL | AT27: 2 | AU27: 20000 | AV27: 0 | AW27: 0 | AX27: 20000 | AY27: 20000 | AZ27: 0 | BA27: 0 | BB27: Ahorro | BC27: Scotiabank Perú | BD27: 000-2768484 | BE27: TRANSFERENCIA BANCARIA | BG27: 7844655656315 | BH27: No | BJ27: 4 | BK27: CANCELADO | BV27: Si | BW27: 45488.655 | BX27: Carla Michue M | BZ27: 6 | CA27: 29/06/2026 01:06 | CB27: 0 | CF27: Cobranzas_2024.csv | CG27: 2024 | CH27: 01/01/2024 | CI27: 31/08/2031
A28: RESIDENCIAL PRADA | B28: Etapa 1 | C28: Edificio | D28: A | E28: Departamento | F28: 201 | G28: 84 | H28: 0 | I28: 622500 | J28: 622500 | AI28: Joseluis Gaspar Zapata Flores | AJ28: 46730672 | AK28: Jr. Los Clavles 141 P. J El Progreso 1er Sector | AM28: 948041027 | AN28: jlzapata91@gmail.com | AO28: LIMA | AP28: CARABAYLLO | AQ28: 45656 | AR28: 45722 | AS28: CUOTA INICIAL | AT28: 3 | AU28: 0 | AV28: 0 | AW28: 0 | AX28: 67000 | AY28: 65000 | AZ28: 0 | BA28: 0 | BB28: Ahorro | BC28: Scotiabank Perú | BD28: 000-2768484 | BE28: TRANSFERENCIA BANCARIA | BG28: u26563 | BH28: No | BJ28: 4 | BK28: CANCELADO | BV28: Si | BW28: 45488.655 | BX28: Carla Michue M | BZ28: 6 | CA28: 29/06/2026 01:07 | CB28: 0 | CF28: Cobranzas_2024.csv | CG28: 2024 | CH28: 01/01/2024 | CI28: 31/08/2031
A29: RESIDENCIAL PRADA | B29: Etapa 1 | C29: Edificio | D29: A | E29: Departamento | F29: 201 | G29: 84 | H29: 0 | I29: 622500 | J29: 622500 | AI29: Joseluis Gaspar Zapata Flores | AJ29: 46730672 | AK29: Jr. Los Clavles 141 P. J El Progreso 1er Sector | AM29: 948041027 | AN29: jlzapata91@gmail.com | AO29: LIMA | AP29: CARABAYLLO | AQ29: 45656 | AR29: 45722 | AS29: CUOTA INICIAL | AT29: 3 | AU29: 67000 | AV29: 0 | AW29: 0 | AX29: 0 | AY29: 2000 | AZ29: 0 | BA29: 0 | BB29: Ahorro | BC29: Scotiabank Perú | BD29: 000-2768484 | BE29: TRANSFERENCIA BANCARIA | BG29: 7844655541508 | BH29: No | BJ29: 4 | BK29: CANCELADO | BV29: Si | BW29: 45488.655 | BX29: Carla Michue M | BZ29: 6 | CA29: 29/06/2026 01:08 | CB29: 0 | CF29: Cobranzas_2024.csv | CG29: 2024 | CH29: 01/01/2024 | CI29: 31/08/2031
A30: RESIDENCIAL PRADA | B30: Etapa 1 | C30: Edificio | D30: A | E30: Departamento | F30: 501 | G30: 83 | H30: 0 | I30: 612000 | J30: 612000 | AI30: Juan Carlos Ángeles Milla | AJ30: 32403305 | AK30: Av. Miraflores 218 | AM30: 942097700 | AN30: Vidang72@hotmail.com | AO30: HUAYLAS | AP30: HUAYLAS | AQ30: 45520 | AR30: 45520 | AS30: SEPARACION | AT30: 1 | AU30: 3000 | AV30: 0 | AW30: 0 | AX30: 3000 | AY30: 3000 | AZ30: 0 | BA30: 0 | BB30: Ahorro | BC30: Scotiabank Perú | BD30: 000-2768484 | BE30: TRANSFERENCIA BANCARIA | BF30: 32403305 | BG30: 02431073 | BH30: No | BI30: NO PRECISA | BJ30: 1 | BK30: CANCELADO | BV30: Si | BW30: 45541.594 | BX30: Carla Michue M | BZ30: 21 | CA30: 29/05/2026 12:21 | CB30: 0 | CF30: Cobranzas_2024.csv | CG30: 2024 | CH30: 01/01/2024 | CI30: 31/08/2031
A31: RESIDENCIAL PRADA | B31: Etapa 1 | C31: Edificio | D31: A | E31: Departamento | F31: 501 | G31: 83 | H31: 0 | I31: 612000 | J31: 612000 | AI31: Juan Carlos Ángeles Milla | AJ31: 32403305 | AK31: Av. Miraflores 218 | AM31: 942097700 | AN31: Vidang72@hotmail.com | AO31: HUAYLAS | AP31: HUAYLAS | AQ31: 45541 | AR31: 45541 | AS31: CUOTA INICIAL | AT31: 2 | AU31: 29500 | AV31: 0 | AW31: 0 | AX31: 29500 | AY31: 29500 | AZ31: 0 | BA31: 0 | BB31: Ahorro | BC31: Scotiabank Perú | BD31: 000-2768484 | BE31: TRANSFERENCIA BANCARIA | BF31: 32403305 | BG31: 0500010059 | BH31: No | BI31: NO PRECISA | BJ31: 1 | BK31: CANCELADO | BV31: Si | BW31: 45541.594 | BX31: Carla Michue M | BZ31: 21 | CA31: 29/05/2026 12:21 | CB31: 0 | CF31: Cobranzas_2024.csv | CG31: 2024 | CH31: 01/01/2024 | CI31: 31/08/2031
A32: RESIDENCIAL PRADA | B32: Etapa 1 | C32: Edificio | D32: A | E32: Departamento | F32: 403 | G32: 88.27 | H32: 0 | I32: 654000 | J32: 654000 | AI32: Liliana Lucila Luciano Claros | AJ32: 15764694 | AK32: MZ M5 – Lt. 7 urb. Paseo del Mar | AM32: 982406857 | AN32: liliana31_micaela@hotmail.com | AO32: SANTA | AP32: NUEVO CHIMBOTE | AQ32: 45586 | AR32: 45586 | AS32: SEPARACION | AT32: 1 | AU32: 3000 | AV32: 0 | AW32: 0 | AX32: 3000 | AY32: 3000 | AZ32: 0 | BA32: 0 | BB32: Crédito Hipotecario | BC32: Scotiabank Perú | BD32: 000-2768484 | BE32: EFECTIVO | BF32: 15764694 | BG32: 0500010056 | BH32: No | BI32: NO PRECISA | BJ32: 1 | BK32: CANCELADO | BV32: Si | BW32: 45619.386 | BX32: Carla Michue M | BZ32: 1 | CA32: 29/05/2026 12:20 | CB32: 0 | CF32: Cobranzas_2024.csv | CG32: 2024 | CH32: 01/01/2024 | CI32: 31/08/2031
A33: RESIDENCIAL PRADA | B33: Etapa 1 | C33: Edificio | D33: A | E33: Departamento | F33: 403 | G33: 88.27 | H33: 0 | I33: 654000 | J33: 654000 | AI33: Liliana Lucila Luciano Claros | AJ33: 15764694 | AK33: MZ M5 – Lt. 7 urb. Paseo del Mar | AM33: 982406857 | AN33: liliana31_micaela@hotmail.com | AO33: SANTA | AP33: NUEVO CHIMBOTE | AQ33: 45619 | AR33: 45619 | AS33: CUOTA INICIAL | AT33: 2 | AU33: 97800 | AV33: 0 | AW33: 0 | AX33: 97800 | AY33: 97800 | AZ33: 0 | BA33: 0 | BB33: Crédito Hipotecario | BC33: Scotiabank Perú | BD33: 000-2768484 | BE33: TRANSFERENCIA BANCARIA | BG33: 12007725 | BH33: No | BJ33: 4 | BK33: CANCELADO | BV33: Si | BW33: 45619.386 | BX33: Carla Michue M | BZ33: 1 | CA33: 07/07/2026 09:30 | CB33: 0 | CF33: Cobranzas_2024.csv | CG33: 2024 | CH33: 01/01/2024 | CI33: 31/08/2031
A34: RESIDENCIAL PRADA | B34: Etapa 1 | C34: Edificio | D34: A | E34: Departamento | F34: 403 | G34: 88.27 | H34: 0 | I34: 654000 | J34: 654000 | AI34: Liliana Lucila Luciano Claros | AJ34: 15764694 | AK34: MZ M5 – Lt. 7 urb. Paseo del Mar | AM34: 982406857 | AN34: liliana31_micaela@hotmail.com | AO34: SANTA | AP34: NUEVO CHIMBOTE | AQ34: 45631 | AR34: 45631 | AS34: CUOTA INICIAL | AT34: 3 | AU34: 30000 | AV34: 0 | AW34: 0 | AX34: 30000 | AY34: 30000 | AZ34: 0 | BA34: 0 | BB34: Crédito Hipotecario | BC34: Scotiabank Perú | BD34: 000-2768484 | BE34: DEPOSITO EN CUENTA | BF34: 15764694 | BG34: 05000010069 | BH34: No | BI34: NO PRECISA | BJ34: 1 | BK34: CANCELADO | BV34: Si | BW34: 45619.386 | BX34: Carla Michue M | BZ34: 1 | CA34: 29/05/2026 12:20 | CB34: 0 | CF34: Cobranzas_2024.csv | CG34: 2024 | CH34: 01/01/2024 | CI34: 31/08/2031
A35: RESIDENCIAL PRADA | B35: Etapa 1 | C35: Edificio | D35: A | E35: Departamento | F35: 403 | G35: 88.27 | H35: 0 | I35: 654000 | J35: 654000 | AI35: Liliana Lucila Luciano Claros | AJ35: 15764694 | AK35: MZ M5 – Lt. 7 urb. Paseo del Mar | AM35: 982406857 | AN35: liliana31_micaela@hotmail.com | AO35: SANTA | AP35: NUEVO CHIMBOTE | AQ35: 45657 | AR35: 45723 | AS35: SALDO FINANCIAR | AT35: 4 | AU35: 523200 | AV35: 0 | AW35: 0 | AX35: 523200 | AY35: 523200 | AZ35: 0 | BA35: 0 | BB35: Crédito Hipotecario | BC35: Scotiabank Perú | BD35: 000-2768484 | BE35: TRANSFERENCIA BANCARIA | BG35: 07032025 | BH35: Si | BJ35: 4 | BK35: CANCELADO | BV35: Si | BW35: 45619.386 | BX35: Carla Michue M | BZ35: 1 | CA35: 07/07/2026 09:31 | CB35: 0 | CF35: Cobranzas_2024.csv | CG35: 2024 | CH35: 01/01/2024 | CI35: 31/08/2031
A36: RESIDENCIAL PRADA | B36: Etapa 1 | C36: Edificio | D36: A | E36: Departamento | F36: 603 | G36: 88.27 | H36: 0 | I36: 654000 | J36: 654000 | AI36: Luis Alberto Ovalle Huamanguilla | AJ36: 43953371 | AK36: JR. NAPO NRO. 821 | AM36: 992764943 | AN36: aovalle2212@gmail.com | AO36: LIMA | AP36: BREÑA | AQ36: 45477 | AR36: 45477 | AS36: SEPARACION | AT36: 1 | AU36: 3000 | AV36: 0 | AW36: 0 | AX36: 3000 | AY36: 3000 | AZ36: 0 | BA36: 0 | BB36: Ahorro | BC36: Scotiabank Perú | BD36: 000-2768484 | BE36: TRANSFERENCIA BANCARIA | BG36: 901866 | BH36: No | BJ36: 4 | BK36: CANCELADO | BV36: Si | BW36: 45567.694 | BX36: Carla Michue M | BZ36: 11 | CA36: 07/07/2026 10:58 | CB36: 0 | CF36: Cobranzas_2024.csv | CG36: 2024 | CH36: 01/01/2024 | CI36: 31/08/2031
A37: RESIDENCIAL PRADA | B37: Etapa 1 | C37: Edificio | D37: A | E37: Departamento | F37: 603 | G37: 88.27 | H37: 0 | I37: 654000 | J37: 654000 | AI37: Luis Alberto Ovalle Huamanguilla | AJ37: 43953371 | AK37: JR. NAPO NRO. 821 | AM37: 992764943 | AN37: aovalle2212@gmail.com | AO37: LIMA | AP37: BREÑA | AQ37: 45656 | AR37: 45567 | AS37: SEPARACION | AT37: 5 | AU37: 5000 | AV37: 0 | AW37: 0 | AX37: 5000 | AY37: 5000 | AZ37: 0 | BA37: 0 | BB37: Ahorro | BC37: Scotiabank Perú | BD37: 000-2768484 | BE37: TRANSFERENCIA BANCARIA | BG37: 06056215 | BH37: No | BJ37: 4 | BK37: CANCELADO | BV37: Si | BW37: 45567.694 | BX37: Carla Michue M | BZ37: 11 | CA37: 07/07/2026 11:03 | CB37: 0 | CF37: Cobranzas_2024.csv | CG37: 2024 | CH37: 01/01/2024 | CI37: 31/08/2031
A38: RESIDENCIAL PRADA | B38: Etapa 1 | C38: Edificio | D38: A | E38: Departamento | F38: 603 | G38: 88.27 | H38: 0 | I38: 654000 | J38: 654000 | AI38: Luis Alberto Ovalle Huamanguilla | AJ38: 43953371 | AK38: JR. NAPO NRO. 821 | AM38: 992764943 | AN38: aovalle2212@gmail.com | AO38: LIMA | AP38: BREÑA | AQ38: 45656 | AR38: 45567 | AS38: CUOTA INICIAL | AT38: 1 | AU38: 57400 | AV38: 0 | AW38: 0 | AX38: 57400 | AY38: 20000 | AZ38: 0 | BA38: 0 | BB38: Ahorro | BC38: Scotiabank Perú | BD38: 000-2768484 | BE38: TRANSFERENCIA BANCARIA | BG38: 06056215 | BH38: No | BJ38: 4 | BK38: CANCELADO | BV38: Si | BW38: 45567.694 | BX38: Carla Michue M | BZ38: 11 | CA38: 07/07/2026 11:03 | CB38: 0 | CF38: Cobranzas_2024.csv | CG38: 2024 | CH38: 01/01/2024 | CI38: 31/08/2031
A39: RESIDENCIAL PRADA | B39: Etapa 1 | C39: Edificio | D39: A | E39: Departamento | F39: 603 | G39: 88.27 | H39: 0 | I39: 654000 | J39: 654000 | AI39: Luis Alberto Ovalle Huamanguilla | AJ39: 43953371 | AK39: JR. NAPO NRO. 821 | AM39: 992764943 | AN39: aovalle2212@gmail.com | AO39: LIMA | AP39: BREÑA | AQ39: 45656 | AR39: 45723 | AS39: CUOTA INICIAL | AT39: 1 | AU39: 0 | AV39: 0 | AW39: 0 | AX39: 0 | AY39: 37400 | AZ39: 0 | BA39: 0 | BB39: Ahorro | BC39: Scotiabank Perú | BD39: 000-2768484 | BE39: TRANSFERENCIA BANCARIA | BG39: U26926 | BH39: No | BJ39: 4 | BK39: CANCELADO | BV39: Si | BW39: 45567.694 | BX39: Carla Michue M | BZ39: 11 | CA39: 07/07/2026 11:04 | CB39: 0 | CF39: Cobranzas_2024.csv | CG39: 2024 | CH39: 01/01/2024 | CI39: 31/08/2031
A40: RESIDENCIAL PRADA | B40: Etapa 1 | C40: Edificio | D40: A | E40: Departamento | F40: 202 | G40: 56 | H40: 0 | I40: 446900 | J40: 446900 | AI40: María Cristina Collazos Romero | AJ40: 31676885 | AK40: Jr. Huandoy 242 | AL40: 969870030 | AM40: 969870030 | AN40: gerenciasnacks1@gmail.com | AO40: HUARAZ | AP40: HUARAZ | AQ40: 45526 | AR40: 45526 | AS40: SEPARACION | AT40: 1 | AU40: 3000 | AV40: 0 | AW40: 0 | AX40: 3000 | AY40: 3000 | AZ40: 0 | BA40: 0 | BB40: Crédito Hipotecario | BC40: Scotiabank Perú | BD40: 000-2768484 | BE40: TRANSFERENCIA BANCARIA | BF40: 31676885 | BG40: 0500010101 | BH40: No | BI40: NO PRECISA | BJ40: 4 | BK40: CANCELADO | BV40: Si | BW40: 45911.607 | BX40: Kenny Salazar S | BZ40: 33 | CA40: 02/06/2026 15:10 | CB40: 0 | CF40: Cobranzas_2024.csv | CG40: 2024 | CH40: 01/01/2024 | CI40: 31/08/2031
...

Sheet Prada
C5: REPORTE DE COBRANZAS
B6: Prada
C8: Vendido | F8: Cobranzas
C9: Monto | D9: Unidades | F9: Avance | G9: Cobrado | H9: Por Cobrar | I9: Vencido | J9: Tasa de Morosidad | K9: Clientes Morosos (unidades) | L9: Dias de Atraso (Promedio)
B11: Departamentos | C11: 24218600 | D11: 58 | F11: =IF(C11=0,0,G11/C11) -> 0.90244358 | G11: =SUM(G12:G13) -> 21855920 | H11: =SUM(H12:H13) -> 460800 | I11: =SUM(I12:I13) -> 1901880 | J11: =IF(C11=0,0,I11/C11) -> 0.078529725 | K11: 6 | L11: 71
B12: Departamento | C12: 16401100 | D12: 31 | F12: =IF(C12=0,0,G12/C12) -> 0.91229674 | G12: =IFERROR(SUMPRODUCT(--ISNUMBER(SEARCH($B$6,Base_Cobranzas!$A$2:$A$814)),--((--ISNUMBER(SEARCH("DEPART",UPPER(Base_Cobranzas!$E$2:$E$814)))+--ISNUMBER(SEARCH("DEPART",UPPER(Base_Cobranzas!$M$2:$M$814)))+--ISNUMBER(SEARCH("DEPART",UPPER(Base_Cobranzas!$U$2:$U$814)))+--ISNUMBER(SEARCH("DEPART",UPPER(Base_Cobranzas!$AC$2:$AC$814))))>0),--((--ISNUMBER(SEARCH("ESTACION",UPPER(Base_Cobranzas!$E$2:$E$814)))+--ISNUMBER(SEARCH("ESTACION",UPPER(Base_Cobranzas!$M$2:$M$814)))+--ISNUMBER(SEARCH("ESTACION",UPPER(Base_Cobranzas!$U$2:$U$814)))+--ISNUMBER(SEARCH("ESTACION",UPPER(Base_Cobranzas!$AC$2:$AC$814))))=0),--(Base_Cobranzas!$AY$2:$AY$814>0),Base_Cobranzas!$AY$2:$AY$814),0) -> 14962670 | H12: =IFERROR(SUMPRODUCT(--ISNUMBER(SEARCH($B$6,Base_Cobranzas!$A$2:$A$814)),--((--ISNUMBER(SEARCH("DEPART",UPPER(Base_Cobranzas!$E$2:$E$814)))+--ISNUMBER(SEARCH("DEPART",UPPER(Base_Cobranzas!$M$2:$M$814)))+--ISNUMBER(SEARCH("DEPART",UPPER(Base_Cobranzas!$U$2:$U$814)))+--ISNUMBER(SEARCH("DEPART",UPPER(Base_Cobranzas!$AC$2:$AC$814))))>0),--((--ISNUMBER(SEARCH("ESTACION",UPPER(Base_Cobranzas!$E$2:$E$814)))+--ISNUMBER(SEARCH("ESTACION",UPPER(Base_Cobranzas!$M$2:$M$814)))+--ISNUMBER(SEARCH("ESTACION",UPPER(Base_Cobranzas!$U$2:$U$814)))+--ISNUMBER(SEARCH("ESTACION",UPPER(Base_Cobranzas!$AC$2:$AC$814))))=0),--ISNUMBER(SEARCH("PENDIENTE",UPPER(TRIM(Base_Cobranzas!$BK$2:$BK$814)))),Base_Cobranzas!$AZ$2:$AZ$814),0) -> 0 | I12: =IFERROR(SUMPRODUCT(--ISNUMBER(SEARCH($B$6,Base_Cobranzas!$A$2:$A$814)),--((--ISNUMBER(SEARCH("DEPART",UPPER(Base_Cobranzas!$E$2:$E$814)))+--ISNUMBER(SEARCH("DEPART",UPPER(Base_Cobranzas!$M$2:$M$814)))+--ISNUMBER(SEARCH("DEPART",UPPER(Base_Cobranzas!$U$2:$U$814)))+--ISNUMBER(SEARCH("DEPART",UPPER(Base_Cobranzas!$AC$2:$AC$814))))>0),--((--ISNUMBER(SEARCH("ESTACION",UPPER(Base_Cobranzas!$E$2:$E$814)))+--ISNUMBER(SEARCH("ESTACION",UPPER(Base_Cobranzas!$M$2:$M$814)))+--ISNUMBER(SEARCH("ESTACION",UPPER(Base_Cobranzas!$U$2:$U$814)))+--ISNUMBER(SEARCH("ESTACION",UPPER(Base_Cobranzas!$AC$2:$AC$814))))=0),--ISNUMBER(SEARCH("VENCIDO",UPPER(TRIM(Base_Cobranzas!$BK$2:$BK$814)))),Base_Cobranzas!$AZ$2:$AZ$814),0) -> 1438430 | J12: =IF(C12=0,0,I12/C12) -> 0.087703264 | K12: 4 | L12: 93
B13: Departamento + Estacionamiento | C13: 7817500 | D13: 27 | F13: =IF(C13=0,0,G13/C13) -> 0.88177166 | G13: =IFERROR(SUMPRODUCT(--ISNUMBER(SEARCH($B$6,Base_Cobranzas!$A$2:$A$814)),--((--ISNUMBER(SEARCH("DEPART",UPPER(Base_Cobranzas!$E$2:$E$814)))+--ISNUMBER(SEARCH("DEPART",UPPER(Base_Cobranzas!$M$2:$M$814)))+--ISNUMBER(SEARCH("DEPART",UPPER(Base_Cobranzas!$U$2:$U$814)))+--ISNUMBER(SEARCH("DEPART",UPPER(Base_Cobranzas!$AC$2:$AC$814))))>0),--((--ISNUMBER(SEARCH("ESTACION",UPPER(Base_Cobranzas!$E$2:$E$814)))+--ISNUMBER(SEARCH("ESTACION",UPPER(Base_Cobranzas!$M$2:$M$814)))+--ISNUMBER(SEARCH("ESTACION",UPPER(Base_Cobranzas!$U$2:$U$814)))+--ISNUMBER(SEARCH("ESTACION",UPPER(Base_Cobranzas!$AC$2:$AC$814))))>0),--(Base_Cobranzas!$AY$2:$AY$814>0),Base_Cobranzas!$AY$2:$AY$814),0) -> 6893250 | H13: =IFERROR(SUMPRODUCT(--ISNUMBER(SEARCH($B$6,Base_Cobranzas!$A$2:$A$814)),--((--ISNUMBER(SEARCH("DEPART",UPPER(Base_Cobranzas!$E$2:$E$814)))+--ISNUMBER(SEARCH("DEPART",UPPER(Base_Cobranzas!$M$2:$M$814)))+--ISNUMBER(SEARCH("DEPART",UPPER(Base_Cobranzas!$U$2:$U$814)))+--ISNUMBER(SEARCH("DEPART",UPPER(Base_Cobranzas!$AC$2:$AC$814))))>0),--((--ISNUMBER(SEARCH("ESTACION",UPPER(Base_Cobranzas!$E$2:$E$814)))+--ISNUMBER(SEARCH("ESTACION",UPPER(Base_Cobranzas!$M$2:$M$814)))+--ISNUMBER(SEARCH("ESTACION",UPPER(Base_Cobranzas!$U$2:$U$814)))+--ISNUMBER(SEARCH("ESTACION",UPPER(Base_Cobranzas!$AC$2:$AC$814))))>0),--ISNUMBER(SEARCH("PENDIENTE",UPPER(TRIM(Base_Cobranzas!$BK$2:$BK$814)))),Base_Cobranzas!$AZ$2:$AZ$814),0) -> 460800 | I13: =IFERROR(SUMPRODUCT(--ISNUMBER(SEARCH($B$6,Base_Cobranzas!$A$2:$A$814)),--((--ISNUMBER(SEARCH("DEPART",UPPER(Base_Cobranzas!$E$2:$E$814)))+--ISNUMBER(SEARCH("DEPART",UPPER(Base_Cobranzas!$M$2:$M$814)))+--ISNUMBER(SEARCH("DEPART",UPPER(Base_Cobranzas!$U$2:$U$814)))+--ISNUMBER(SEARCH("DEPART",UPPER(Base_Cobranzas!$AC$2:$AC$814))))>0),--((--ISNUMBER(SEARCH("ESTACION",UPPER(Base_Cobranzas!$E$2:$E$814)))+--ISNUMBER(SEARCH("ESTACION",UPPER(Base_Cobranzas!$M$2:$M$814)))+--ISNUMBER(SEARCH("ESTACION",UPPER(Base_Cobranzas!$U$2:$U$814)))+--ISNUMBER(SEARCH("ESTACION",UPPER(Base_Cobranzas!$AC$2:$AC$814))))>0),--ISNUMBER(SEARCH("VENCIDO",UPPER(TRIM(Base_Cobranzas!$BK$2:$BK$814)))),Base_Cobranzas!$AZ$2:$AZ$814),0) -> 463450 | J13: =IF(C13=0,0,I13/C13) -> 0.059283658 | K13: 2 | L13: 19
B15: Estacionamientos | C15: 807100 | D15: 15 | F15: =IF(C15=0,0,G15/C15) -> 0.79099269 | G15: =IFERROR(SUMPRODUCT(--ISNUMBER(SEARCH($B$6,Base_Cobranzas!$A$2:$A$814)),--((--ISNUMBER(SEARCH("DEPART",UPPER(Base_Cobranzas!$E$2:$E$814)))+--ISNUMBER(SEARCH("DEPART",UPPER(Base_Cobranzas!$M$2:$M$814)))+--ISNUMBER(SEARCH("DEPART",UPPER(Base_Cobranzas!$U$2:$U$814)))+--ISNUMBER(SEARCH("DEPART",UPPER(Base_Cobranzas!$AC$2:$AC$814))))=0),--((--ISNUMBER(SEARCH("ESTACION",UPPER(Base_Cobranzas!$E$2:$E$814)))+--ISNUMBER(SEARCH("ESTACION",UPPER(Base_Cobranzas!$M$2:$M$814)))+--ISNUMBER(SEARCH("ESTACION",UPPER(Base_Cobranzas!$U$2:$U$814)))+--ISNUMBER(SEARCH("ESTACION",UPPER(Base_Cobranzas!$AC$2:$AC$814))))>0),--(Base_Cobranzas!$AY$2:$AY$814>0),Base_Cobranzas!$AY$2:$AY$814),0) -> 638410.2 | H15: =IFERROR(SUMPRODUCT(--ISNUMBER(SEARCH($B$6,Base_Cobranzas!$A$2:$A$814)),--((--ISNUMBER(SEARCH("DEPART",UPPER(Base_Cobranzas!$E$2:$E$814)))+--ISNUMBER(SEARCH("DEPART",UPPER(Base_Cobranzas!$M$2:$M$814)))+--ISNUMBER(SEARCH("DEPART",UPPER(Base_Cobranzas!$U$2:$U$814)))+--ISNUMBER(SEARCH("DEPART",UPPER(Base_Cobranzas!$AC$2:$AC$814))))=0),--((--ISNUMBER(SEARCH("ESTACION",UPPER(Base_Cobranzas!$E$2:$E$814)))+--ISNUMBER(SEARCH("ESTACION",UPPER(Base_Cobranzas!$M$2:$M$814)))+--ISNUMBER(SEARCH("ESTACION",UPPER(Base_Cobranzas!$U$2:$U$814)))+--ISNUMBER(SEARCH("ESTACION",UPPER(Base_Cobranzas!$AC$2:$AC$814))))>0),--ISNUMBER(SEARCH("PENDIENTE",UPPER(TRIM(Base_Cobranzas!$BK$2:$BK$814)))),Base_Cobranzas!$AZ$2:$AZ$814),0) -> 73889.8 | I15: =IFERROR(SUMPRODUCT(--ISNUMBER(SEARCH($B$6,Base_Cobranzas!$A$2:$A$814)),--((--ISNUMBER(SEARCH("DEPART",UPPER(Base_Cobranzas!$E$2:$E$814)))+--ISNUMBER(SEARCH("DEPART",UPPER(Base_Cobranzas!$M$2:$M$814)))+--ISNUMBER(SEARCH("DEPART",UPPER(Base_Cobranzas!$U$2:$U$814)))+--ISNUMBER(SEARCH("DEPART",UPPER(Base_Cobranzas!$AC$2:$AC$814))))=0),--((--ISNUMBER(SEARCH("ESTACION",UPPER(Base_Cobranzas!$E$2:$E$814)))+--ISNUMBER(SEARCH("ESTACION",UPPER(Base_Cobranzas!$M$2:$M$814)))+--ISNUMBER(SEARCH("ESTACION",UPPER(Base_Cobranzas!$U$2:$U$814)))+--ISNUMBER(SEARCH("ESTACION",UPPER(Base_Cobranzas!$AC$2:$AC$814))))>0),--ISNUMBER(SEARCH("VENCIDO",UPPER(TRIM(Base_Cobranzas!$BK$2:$BK$814)))),Base_Cobranzas!$AZ$2:$AZ$814),0) -> 94800 | J15: =IF(C15=0,0,I15/C15) -> 0.11745756 | K15: 5 | L15: 40
B17: Depositos | C17: 0 | D17: 0 | F17: =IF(C17=0,0,G17/C17) -> 0 | G17: =IFERROR(SUMPRODUCT(--ISNUMBER(SEARCH($B$6,Base_Cobranzas!$A$2:$A$814)),--((--ISNUMBER(SEARCH("DEPART",UPPER(Base_Cobranzas!$E$2:$E$814)))+--ISNUMBER(SEARCH("DEPART",UPPER(Base_Cobranzas!$M$2:$M$814)))+--ISNUMBER(SEARCH("DEPART",UPPER(Base_Cobranzas!$U$2:$U$814)))+--ISNUMBER(SEARCH("DEPART",UPPER(Base_Cobranzas!$AC$2:$AC$814))))=0),--((--ISNUMBER(SEARCH("ESTACION",UPPER(Base_Cobranzas!$E$2:$E$814)))+--ISNUMBER(SEARCH("ESTACION",UPPER(Base_Cobranzas!$M$2:$M$814)))+--ISNUMBER(SEARCH("ESTACION",UPPER(Base_Cobranzas!$U$2:$U$814)))+--ISNUMBER(SEARCH("ESTACION",UPPER(Base_Cobranzas!$AC$2:$AC$814))))=0),--((--ISNUMBER(SEARCH("DEPOS",UPPER(Base_Cobranzas!$E$2:$E$814)))+--ISNUMBER(SEARCH("DEPOS",UPPER(Base_Cobranzas!$M$2:$M$814)))+--ISNUMBER(SEARCH("DEPOS",UPPER(Base_Cobranzas!$U$2:$U$814)))+--ISNUMBER(SEARCH("DEPOS",UPPER(Base_Cobranzas!$AC$2:$AC$814))))>0),--(Base_Cobranzas!$AY$2:$AY$814>0),Base_Cobranzas!$AY$2:$AY$814),0) -> 0 | H17: =IFERROR(SUMPRODUCT(--ISNUMBER(SEARCH($B$6,Base_Cobranzas!$A$2:$A$814)),--((--ISNUMBER(SEARCH("DEPART",UPPER(Base_Cobranzas!$E$2:$E$814)))+--ISNUMBER(SEARCH("DEPART",UPPER(Base_Cobranzas!$M$2:$M$814)))+--ISNUMBER(SEARCH("DEPART",UPPER(Base_Cobranzas!$U$2:$U$814)))+--ISNUMBER(SEARCH("DEPART",UPPER(Base_Cobranzas!$AC$2:$AC$814))))=0),--((--ISNUMBER(SEARCH("ESTACION",UPPER(Base_Cobranzas!$E$2:$E$814)))+--ISNUMBER(SEARCH("ESTACION",UPPER(Base_Cobranzas!$M$2:$M$814)))+--ISNUMBER(SEARCH("ESTACION",UPPER(Base_Cobranzas!$U$2:$U$814)))+--ISNUMBER(SEARCH("ESTACION",UPPER(Base_Cobranzas!$AC$2:$AC$814))))=0),--((--ISNUMBER(SEARCH("DEPOS",UPPER(Base_Cobranzas!$E$2:$E$814)))+--ISNUMBER(SEARCH("DEPOS",UPPER(Base_Cobranzas!$M$2:$M$814)))+--ISNUMBER(SEARCH("DEPOS",UPPER(Base_Cobranzas!$U$2:$U$814)))+--ISNUMBER(SEARCH("DEPOS",UPPER(Base_Cobranzas!$AC$2:$AC$814))))>0),--ISNUMBER(SEARCH("PENDIENTE",UPPER(TRIM(Base_Cobranzas!$BK$2:$BK$814)))),Base_Cobranzas!$AZ$2:$AZ$814),0) -> 0 | I17: =IFERROR(SUMPRODUCT(--ISNUMBER(SEARCH($B$6,Base_Cobranzas!$A$2:$A$814)),--((--ISNUMBER(SEARCH("DEPART",UPPER(Base_Cobranzas!$E$2:$E$814)))+--ISNUMBER(SEARCH("DEPART",UPPER(Base_Cobranzas!$M$2:$M$814)))+--ISNUMBER(SEARCH("DEPART",UPPER(Base_Cobranzas!$U$2:$U$814)))+--ISNUMBER(SEARCH("DEPART",UPPER(Base_Cobranzas!$AC$2:$AC$814))))=0),--((--ISNUMBER(SEARCH("ESTACION",UPPER(Base_Cobranzas!$E$2:$E$814)))+--ISNUMBER(SEARCH("ESTACION",UPPER(Base_Cobranzas!$M$2:$M$814)))+--ISNUMBER(SEARCH("ESTACION",UPPER(Base_Cobranzas!$U$2:$U$814)))+--ISNUMBER(SEARCH("ESTACION",UPPER(Base_Cobranzas!$AC$2:$AC$814))))=0),--((--ISNUMBER(SEARCH("DEPOS",UPPER(Base_Cobranzas!$E$2:$E$814)))+--ISNUMBER(SEARCH("DEPOS",UPPER(Base_Cobranzas!$M$2:$M$814)))+--ISNUMBER(SEARCH("DEPOS",UPPER(Base_Cobranzas!$U$2:$U$814)))+--ISNUMBER(SEARCH("DEPOS",UPPER(Base_Cobranzas!$AC$2:$AC$814))))>0),--ISNUMBER(SEARCH("VENCIDO",UPPER(TRIM(Base_Cobranzas!$BK$2:$BK$814)))),Base_Cobranzas!$AZ$2:$AZ$814),0) -> 0 | J17: =IF(C17=0,0,I17/C17) -> 0 | K17: 0 | L17: 0
B19: Local Comercial | C19: 0 | D19: 0 | F19: =IF(C19=0,0,G19/C19) -> 0 | G19: =IFERROR(SUMPRODUCT(--ISNUMBER(SEARCH($B$6,Base_Cobranzas!$A$2:$A$814)),--(((--ISNUMBER(SEARCH("LOCAL",UPPER(Base_Cobranzas!$E$2:$E$814)))+--ISNUMBER(SEARCH("LOCAL",UPPER(Base_Cobranzas!$M$2:$M$814)))+--ISNUMBER(SEARCH("LOCAL",UPPER(Base_Cobranzas!$U$2:$U$814)))+--ISNUMBER(SEARCH("LOCAL",UPPER(Base_Cobranzas!$AC$2:$AC$814))))+(--ISNUMBER(SEARCH("COMERCIAL",UPPER(Base_Cobranzas!$E$2:$E$814)))+--ISNUMBER(SEARCH("COMERCIAL",UPPER(Base_Cobranzas!$M$2:$M$814)))+--ISNUMBER(SEARCH("COMERCIAL",UPPER(Base_Cobranzas!$U$2:$U$814)))+--ISNUMBER(SEARCH("COMERCIAL",UPPER(Base_Cobranzas!$AC$2:$AC$814)))))>0),--(Base_Cobranzas!$AY$2:$AY$814>0),Base_Cobranzas!$AY$2:$AY$814),0) -> 0 | H19: =IFERROR(SUMPRODUCT(--ISNUMBER(SEARCH($B$6,Base_Cobranzas!$A$2:$A$814)),--(((--ISNUMBER(SEARCH("LOCAL",UPPER(Base_Cobranzas!$E$2:$E$814)))+--ISNUMBER(SEARCH("LOCAL",UPPER(Base_Cobranzas!$M$2:$M$814)))+--ISNUMBER(SEARCH("LOCAL",UPPER(Base_Cobranzas!$U$2:$U$814)))+--ISNUMBER(SEARCH("LOCAL",UPPER(Base_Cobranzas!$AC$2:$AC$814))))+(--ISNUMBER(SEARCH("COMERCIAL",UPPER(Base_Cobranzas!$E$2:$E$814)))+--ISNUMBER(SEARCH("COMERCIAL",UPPER(Base_Cobranzas!$M$2:$M$814)))+--ISNUMBER(SEARCH("COMERCIAL",UPPER(Base_Cobranzas!$U$2:$U$814)))+--ISNUMBER(SEARCH("COMERCIAL",UPPER(Base_Cobranzas!$AC$2:$AC$814)))))>0),--ISNUMBER(SEARCH("PENDIENTE",UPPER(TRIM(Base_Cobranzas!$BK$2:$BK$814)))),Base_Cobranzas!$AZ$2:$AZ$814),0) -> 0 | I19: =IFERROR(SUMPRODUCT(--ISNUMBER(SEARCH($B$6,Base_Cobranzas!$A$2:$A$814)),--(((--ISNUMBER(SEARCH("LOCAL",UPPER(Base_Cobranzas!$E$2:$E$814)))+--ISNUMBER(SEARCH("LOCAL",UPPER(Base_Cobranzas!$M$2:$M$814)))+--ISNUMBER(SEARCH("LOCAL",UPPER(Base_Cobranzas!$U$2:$U$814)))+--ISNUMBER(SEARCH("LOCAL",UPPER(Base_Cobranzas!$AC$2:$AC$814))))+(--ISNUMBER(SEARCH("COMERCIAL",UPPER(Base_Cobranzas!$E$2:$E$814)))+--ISNUMBER(SEARCH("COMERCIAL",UPPER(Base_Cobranzas!$M$2:$M$814)))+--ISNUMBER(SEARCH("COMERCIAL",UPPER(Base_Cobranzas!$U$2:$U$814)))+--ISNUMBER(SEARCH("COMERCIAL",UPPER(Base_Cobranzas!$AC$2:$AC$814)))))>0),--ISNUMBER(SEARCH("VENCIDO",UPPER(TRIM(Base_Cobranzas!$BK$2:$BK$814)))),Base_Cobranzas!$AZ$2:$AZ$814),0) -> 0 | J19: =IF(C19=0,0,I19/C19) -> 0 | K19: 0 | L19: 0
A21: =+IF(ROUND(C21,0)=ROUND(G21+H21+I21,0),"OK","REVISAR") -> OK | B21: Total | C21: 25025700 | D21: 73 | F21: =IF(C21=0,0,G21/C21) -> 0.89884919 | G21: =G11+G15+G17+G19 -> 22494330 | H21: =H11+H15+H17+H19 -> 534689.8 | I21: =I11+I15+I17+I19 -> 1996680 | J21: =IF(C21=0,0,I21/C21) -> 0.079785181 | K21: 11 | L21: 58
B31: COBRANZA REAL
B33: Tipo de Credito | C33: 2024 | D33: 2025 | E33: 46023 | F33: 46054 | G33: 46082 | H33: 46113 | I33: 46143 | J33: 46174 | K33: 46204 | L33: 46235 | M33: Total
B34: Crédito Directo | C34: =IFERROR(SUMPRODUCT(--ISNUMBER(SEARCH($B$6,Base_Cobranzas!$A$2:$A$814)),--(Base_Cobranzas!$AR$2:$AR$814>=IF(C$33<3000,DATE(C$33,1,1),C$33)),--(Base_Cobranzas!$AR$2:$AR$814<IF(C$33<3000,DATE(C$33+1,1,1),EDATE(C$33,1))),--ISNUMBER(SEARCH(IF(ISNUMBER(SEARCH("DIRECTO",UPPER($B34))),"DIRECTO",IF(ISNUMBER(SEARCH("HIPOT",UPPER($B34))),"HIPOT",IF(ISNUMBER(SEARCH("AHORRO",UPPER($B34))),"AHORRO",UPPER($B34)))),UPPER(Base_Cobranzas!$BB$2:$BB$814))),--(Base_Cobranzas!$AY$2:$AY$814>0),Base_Cobranzas!$AY$2:$AY$814),0) -> 542725 | D34: =IFERROR(SUMPRODUCT(--ISNUMBER(SEARCH($B$6,Base_Cobranzas!$A$2:$A$814)),--(Base_Cobranzas!$AR$2:$AR$814>=IF(D$33<3000,DATE(D$33,1,1),D$33)),--(Base_Cobranzas!$AR$2:$AR$814<IF(D$33<3000,DATE(D$33+1,1,1),EDATE(D$33,1))),--ISNUMBER(SEARCH(IF(ISNUMBER(SEARCH("DIRECTO",UPPER($B34))),"DIRECTO",IF(ISNUMBER(SEARCH("HIPOT",UPPER($B34))),"HIPOT",IF(ISNUMBER(SEARCH("AHORRO",UPPER($B34))),"AHORRO",UPPER($B34)))),UPPER(Base_Cobranzas!$BB$2:$BB$814))),--(Base_Cobranzas!$AY$2:$AY$814>0),Base_Cobranzas!$AY$2:$AY$814),0) -> 2280048.6 | E34: =IFERROR(SUMPRODUCT(--ISNUMBER(SEARCH($B$6,Base_Cobranzas!$A$2:$A$814)),--(Base_Cobranzas!$AR$2:$AR$814>=IF(E$33<3000,DATE(E$33,1,1),E$33)),--(Base_Cobranzas!$AR$2:$AR$814<IF(E$33<3000,DATE(E$33+1,1,1),EDATE(E$33,1))),--ISNUMBER(SEARCH(IF(ISNUMBER(SEARCH("DIRECTO",UPPER($B34))),"DIRECTO",IF(ISNUMBER(SEARCH("HIPOT",UPPER($B34))),"HIPOT",IF(ISNUMBER(SEARCH("AHORRO",UPPER($B34))),"AHORRO",UPPER($B34)))),UPPER(Base_Cobranzas!$BB$2:$BB$814))),--(Base_Cobranzas!$AY$2:$AY$814>0),Base_Cobranzas!$AY$2:$AY$814),0) -> 202837.5 | F34: =IFERROR(SUMPRODUCT(--ISNUMBER(SEARCH($B$6,Base_Cobranzas!$A$2:$A$814)),--(Base_Cobranzas!$AR$2:$AR$814>=IF(F$33<3000,DATE(F$33,1,1),F$33)),--(Base_Cobranzas!$AR$2:$AR$814<IF(F$33<3000,DATE(F$33+1,1,1),EDATE(F$33,1))),--ISNUMBER(SEARCH(IF(ISNUMBER(SEARCH("DIRECTO",UPPER($B34))),"DIRECTO",IF(ISNUMBER(SEARCH("HIPOT",UPPER($B34))),"HIPOT",IF(ISNUMBER(SEARCH("AHORRO",UPPER($B34))),"AHORRO",UPPER($B34)))),UPPER(Base_Cobranzas!$BB$2:$BB$814))),--(Base_Cobranzas!$AY$2:$AY$814>0),Base_Cobranzas!$AY$2:$AY$814),0) -> 302117.48 | G34: =IFERROR(SUMPRODUCT(--ISNUMBER(SEARCH($B$6,Base_Cobranzas!$A$2:$A$814)),--(Base_Cobranzas!$AR$2:$AR$814>=IF(G$33<3000,DATE(G$33,1,1),G$33)),--(Base_Cobranzas!$AR$2:$AR$814<IF(G$33<3000,DATE(G$33+1,1,1),EDATE(G$33,1))),--ISNUMBER(SEARCH(IF(ISNUMBER(SEARCH("DIRECTO",UPPER($B34))),"DIRECTO",IF(ISNUMBER(SEARCH("HIPOT",UPPER($B34))),"HIPOT",IF(ISNUMBER(SEARCH("AHORRO",UPPER($B34))),"AHORRO",UPPER($B34)))),UPPER(Base_Cobranzas!$BB$2:$BB$814))),--(Base_Cobranzas!$AY$2:$AY$814>0),Base_Cobranzas!$AY$2:$AY$814),0) -> 311500 | H34: =IFERROR(SUMPRODUCT(--ISNUMBER(SEARCH($B$6,Base_Cobranzas!$A$2:$A$814)),--(Base_Cobranzas!$AR$2:$AR$814>=IF(H$33<3000,DATE(H$33,1,1),H$33)),--(Base_Cobranzas!$AR$2:$AR$814<IF(H$33<3000,DATE(H$33+1,1,1),EDATE(H$33,1))),--ISNUMBER(SEARCH(IF(ISNUMBER(SEARCH("DIRECTO",UPPER($B34))),"DIRECTO",IF(ISNUMBER(SEARCH("HIPOT",UPPER($B34))),"HIPOT",IF(ISNUMBER(SEARCH("AHORRO",UPPER($B34))),"AHORRO",UPPER($B34)))),UPPER(Base_Cobranzas!$BB$2:$BB$814))),--(Base_Cobranzas!$AY$2:$AY$814>0),Base_Cobranzas!$AY$2:$AY$814),0) -> 25000 | I34: =IFERROR(SUMPRODUCT(--ISNUMBER(SEARCH($B$6,Base_Cobranzas!$A$2:$A$814)),--(Base_Cobranzas!$AR$2:$AR$814>=IF(I$33<3000,DATE(I$33,1,1),I$33)),--(Base_Cobranzas!$AR$2:$AR$814<IF(I$33<3000,DATE(I$33+1,1,1),EDATE(I$33,1))),--ISNUMBER(SEARCH(IF(ISNUMBER(SEARCH("DIRECTO",UPPER($B34))),"DIRECTO",IF(ISNUMBER(SEARCH("HIPOT",UPPER($B34))),"HIPOT",IF(ISNUMBER(SEARCH("AHORRO",UPPER($B34))),"AHORRO",UPPER($B34)))),UPPER(Base_Cobranzas!$BB$2:$BB$814))),--(Base_Cobranzas!$AY$2:$AY$814>0),Base_Cobranzas!$AY$2:$AY$814),0) -> 204171.42 | J34: =IFERROR(SUMPRODUCT(--ISNUMBER(SEARCH($B$6,Base_Cobranzas!$A$2:$A$814)),--(Base_Cobranzas!$AR$2:$AR$814>=IF(J$33<3000,DATE(J$33,1,1),J$33)),--(Base_Cobranzas!$AR$2:$AR$814<IF(J$33<3000,DATE(J$33+1,1,1),EDATE(J$33,1))),--ISNUMBER(SEARCH(IF(ISNUMBER(SEARCH("DIRECTO",UPPER($B34))),"DIRECTO",IF(ISNUMBER(SEARCH("HIPOT",UPPER($B34))),"HIPOT",IF(ISNUMBER(SEARCH("AHORRO",UPPER($B34))),"AHORRO",UPPER($B34)))),UPPER(Base_Cobranzas!$BB$2:$BB$814))),--(Base_Cobranzas!$AY$2:$AY$814>0),Base_Cobranzas!$AY$2:$AY$814),0) -> 472110.2 | ... L34: =IFERROR(SUMPRODUCT(--ISNUMBER(SEARCH($B$6,Base_Cobranzas!$A$2:$A$814)),--(Base_Cobranzas!$AR$2:$AR$814>=IF(L$33<3000,DATE(L$33,1,1),L$33)),--(Base_Cobranzas!$AR$2:$AR$814<IF(L$33<3000,DATE(L$33+1,1,1),EDATE(L$33,1))),--ISNUMBER(SEARCH(IF(ISNUMBER(SEARCH("DIRECTO",UPPER($B34))),"DIRECTO",IF(ISNUMBER(SEARCH("HIPOT",UPPER($B34))),"HIPOT",IF(ISNUMBER(SEARCH("AHORRO",UPPER($B34))),"AHORRO",UPPER($B34)))),UPPER(Base_Cobranzas!$BB$2:$BB$814))),--(Base_Cobranzas!$AY$2:$AY$814>0),Base_Cobranzas!$AY$2:$AY$814),0) -> 100900 | M34: =SUM(C34:L34) -> 4458910.2
B35: Crédito Hipotecario | C35: =IFERROR(SUMPRODUCT(--ISNUMBER(SEARCH($B$6,Base_Cobranzas!$A$2:$A$814)),--(Base_Cobranzas!$AR$2:$AR$814>=IF(C$33<3000,DATE(C$33,1,1),C$33)),--(Base_Cobranzas!$AR$2:$AR$814<IF(C$33<3000,DATE(C$33+1,1,1),EDATE(C$33,1))),--ISNUMBER(SEARCH(IF(ISNUMBER(SEARCH("DIRECTO",UPPER($B35))),"DIRECTO",IF(ISNUMBER(SEARCH("HIPOT",UPPER($B35))),"HIPOT",IF(ISNUMBER(SEARCH("AHORRO",UPPER($B35))),"AHORRO",UPPER($B35)))),UPPER(Base_Cobranzas!$BB$2:$BB$814))),--(Base_Cobranzas!$AY$2:$AY$814>0),Base_Cobranzas!$AY$2:$AY$814),0) -> 468490 | D35: =IFERROR(SUMPRODUCT(--ISNUMBER(SEARCH($B$6,Base_Cobranzas!$A$2:$A$814)),--(Base_Cobranzas!$AR$2:$AR$814>=IF(D$33<3000,DATE(D$33,1,1),D$33)),--(Base_Cobranzas!$AR$2:$AR$814<IF(D$33<3000,DATE(D$33+1,1,1),EDATE(D$33,1))),--ISNUMBER(SEARCH(IF(ISNUMBER(SEARCH("DIRECTO",UPPER($B35))),"DIRECTO",IF(ISNUMBER(SEARCH("HIPOT",UPPER($B35))),"HIPOT",IF(ISNUMBER(SEARCH("AHORRO",UPPER($B35))),"AHORRO",UPPER($B35)))),UPPER(Base_Cobranzas!$BB$2:$BB$814))),--(Base_Cobranzas!$AY$2:$AY$814>0),Base_Cobranzas!$AY$2:$AY$814),0) -> 9286060 | E35: =IFERROR(SUMPRODUCT(--ISNUMBER(SEARCH($B$6,Base_Cobranzas!$A$2:$A$814)),--(Base_Cobranzas!$AR$2:$AR$814>=IF(E$33<3000,DATE(E$33,1,1),E$33)),--(Base_Cobranzas!$AR$2:$AR$814<IF(E$33<3000,DATE(E$33+1,1,1),EDATE(E$33,1))),--ISNUMBER(SEARCH(IF(ISNUMBER(SEARCH("DIRECTO",UPPER($B35))),"DIRECTO",IF(ISNUMBER(SEARCH("HIPOT",UPPER($B35))),"HIPOT",IF(ISNUMBER(SEARCH("AHORRO",UPPER($B35))),"AHORRO",UPPER($B35)))),UPPER(Base_Cobranzas!$BB$2:$BB$814))),--(Base_Cobranzas!$AY$2:$AY$814>0),Base_Cobranzas!$AY$2:$AY$814),0) -> 1005350 | F35: =IFERROR(SUMPRODUCT(--ISNUMBER(SEARCH($B$6,Base_Cobranzas!$A$2:$A$814)),--(Base_Cobranzas!$AR$2:$AR$814>=IF(F$33<3000,DATE(F$33,1,1),F$33)),--(Base_Cobranzas!$AR$2:$AR$814<IF(F$33<3000,DATE(F$33+1,1,1),EDATE(F$33,1))),--ISNUMBER(SEARCH(IF(ISNUMBER(SEARCH("DIRECTO",UPPER($B35))),"DIRECTO",IF(ISNUMBER(SEARCH("HIPOT",UPPER($B35))),"HIPOT",IF(ISNUMBER(SEARCH("AHORRO",UPPER($B35))),"AHORRO",UPPER($B35)))),UPPER(Base_Cobranzas!$BB$2:$BB$814))),--(Base_Cobranzas!$AY$2:$AY$814>0),Base_Cobranzas!$AY$2:$AY$814),0) -> 117514 | G35: =IFERROR(SUMPRODUCT(--ISNUMBER(SEARCH($B$6,Base_Cobranzas!$A$2:$A$814)),--(Base_Cobranzas!$AR$2:$AR$814>=IF(G$33<3000,DATE(G$33,1,1),G$33)),--(Base_Cobranzas!$AR$2:$AR$814<IF(G$33<3000,DATE(G$33+1,1,1),EDATE(G$33,1))),--ISNUMBER(SEARCH(IF(ISNUMBER(SEARCH("DIRECTO",UPPER($B35))),"DIRECTO",IF(ISNUMBER(SEARCH("HIPOT",UPPER($B35))),"HIPOT",IF(ISNUMBER(SEARCH("AHORRO",UPPER($B35))),"AHORRO",UPPER($B35)))),UPPER(Base_Cobranzas!$BB$2:$BB$814))),--(Base_Cobranzas!$AY$2:$AY$814>0),Base_Cobranzas!$AY$2:$AY$814),0) -> 909875.7 | H35: =IFERROR(SUMPRODUCT(--ISNUMBER(SEARCH($B$6,Base_Cobranzas!$A$2:$A$814)),--(Base_Cobranzas!$AR$2:$AR$814>=IF(H$33<3000,DATE(H$33,1,1),H$33)),--(Base_Cobranzas!$AR$2:$AR$814<IF(H$33<3000,DATE(H$33+1,1,1),EDATE(H$33,1))),--ISNUMBER(SEARCH(IF(ISNUMBER(SEARCH("DIRECTO",UPPER($B35))),"DIRECTO",IF(ISNUMBER(SEARCH("HIPOT",UPPER($B35))),"HIPOT",IF(ISNUMBER(SEARCH("AHORRO",UPPER($B35))),"AHORRO",UPPER($B35)))),UPPER(Base_Cobranzas!$BB$2:$BB$814))),--(Base_Cobranzas!$AY$2:$AY$814>0),Base_Cobranzas!$AY$2:$AY$814),0) -> 170810.3 | I35: =IFERROR(SUMPRODUCT(--ISNUMBER(SEARCH($B$6,Base_Cobranzas!$A$2:$A$814)),--(Base_Cobranzas!$AR$2:$AR$814>=IF(I$33<3000,DATE(I$33,1,1),I$33)),--(Base_Cobranzas!$AR$2:$AR$814<IF(I$33<3000,DATE(I$33+1,1,1),EDATE(I$33,1))),--ISNUMBER(SEARCH(IF(ISNUMBER(SEARCH("DIRECTO",UPPER($B35))),"DIRECTO",IF(ISNUMBER(SEARCH("HIPOT",UPPER($B35))),"HIPOT",IF(ISNUMBER(SEARCH("AHORRO",UPPER($B35))),"AHORRO",UPPER($B35)))),UPPER(Base_Cobranzas!$BB$2:$BB$814))),--(Base_Cobranzas!$AY$2:$AY$814>0),Base_Cobranzas!$AY$2:$AY$814),0) -> 850400 | J35: =IFERROR(SUMPRODUCT(--ISNUMBER(SEARCH($B$6,Base_Cobranzas!$A$2:$A$814)),--(Base_Cobranzas!$AR$2:$AR$814>=IF(J$33<3000,DATE(J$33,1,1),J$33)),--(Base_Cobranzas!$AR$2:$AR$814<IF(J$33<3000,DATE(J$33+1,1,1),EDATE(J$33,1))),--ISNUMBER(SEARCH(IF(ISNUMBER(SEARCH("DIRECTO",UPPER($B35))),"DIRECTO",IF(ISNUMBER(SEARCH("HIPOT",UPPER($B35))),"HIPOT",IF(ISNUMBER(SEARCH("AHORRO",UPPER($B35))),"AHORRO",UPPER($B35)))),UPPER(Base_Cobranzas!$BB$2:$BB$814))),--(Base_Cobranzas!$AY$2:$AY$814>0),Base_Cobranzas!$AY$2:$AY$814),0) -> 273650 | ... L35: =IFERROR(SUMPRODUCT(--ISNUMBER(SEARCH($B$6,Base_Cobranzas!$A$2:$A$814)),--(Base_Cobranzas!$AR$2:$AR$814>=IF(L$33<3000,DATE(L$33,1,1),L$33)),--(Base_Cobranzas!$AR$2:$AR$814<IF(L$33<3000,DATE(L$33+1,1,1),EDATE(L$33,1))),--ISNUMBER(SEARCH(IF(ISNUMBER(SEARCH("DIRECTO",UPPER($B35))),"DIRECTO",IF(ISNUMBER(SEARCH("HIPOT",UPPER($B35))),"HIPOT",IF(ISNUMBER(SEARCH("AHORRO",UPPER($B35))),"AHORRO",UPPER($B35)))),UPPER(Base_Cobranzas!$BB$2:$BB$814))),--(Base_Cobranzas!$AY$2:$AY$814>0),Base_Cobranzas!$AY$2:$AY$814),0) -> 200000 | M35: =SUM(C35:L35) -> 13679150
