Workbook

Sheet Reporte_Proyecto
A1: RESUMEN DE COBRANZAS
A4: Proyecto | B4: Precio Venta | C4: Cobrado | D4: Por Cobrar | E4: Vencido | F4: Tasa Morosidad | G4: Cantidad de Clientes Morosos | H4: Días de Atraso Promedio
A5: Beyond | B5: 21736300 | C5: 4849364.2 | D5: 8479306.6 | E5: 8403829.2 | F5: 0.38662648 | G5: 31 | H5: 134 | I5: =IF(ROUND(B5,0)=ROUND(C5+D5+E5,0),"OK","REVISAR")
A6: Prada | B6: 26220000 | C6: 23425730 | D6: 34989.8 | E6: 2759280 | F6: 0.1052357 | G6: 12 | H6: 74 | I6: =IF(ROUND(B6,0)=ROUND(C6+D6+E6,0),"OK","REVISAR")
A7: Venecia | B7: 8984700 | C7: 4670086.7 | D7: 2410647.4 | E7: 1903965.9 | F7: 0.21191202 | G7: 10 | H7: 43 | I7: =IF(ROUND(B7,0)=ROUND(C7+D7+E7,0),"OK","REVISAR")
A8: TOTAL | B8: 56941000 | C8: 32945181 | D8: 10924944 | E8: 13067075 | F8: 0.22948447 | G8: 53 | H8: 61 | I8: =IF(ROUND(B8,0)=ROUND(C8+D8+E8,0),"OK","REVISAR")

Sheet Reporte_General
A1: REPORTE DE COBRANZAS
C4: DEUDA TOTAL | G4: CLIENTES CON DEUDA
C5: 13067075 | G5: 53
A7: PRADA | F7: DEUDA TOTAL | H7: 2759280 | J7: CLIENTE | L7: 12
A8: Rank | B8: Cliente | F8: Unidad | G8: Financiamiento | H8: Precio Venta | I8: Monto Cobrado | J8: Monto Deuda | L8: Tasa de Morosidad | M8: Días de atraso
A9: 1 | B9: katherine Neyra Alor Neyra | F9: Dpto 405, Estc E 35 - D 27 | G9: Crédito Hipotecario | H9: 535000 | I9: 3000 | J9: 532000 | L9: 0.99439252 | M9: 93
A10: 2 | B10: RODRIGO SANDRO CARDENAS BULLON | F10: Dpto 402, Estc E 46 - D 35 | G10: Ahorro | H10: 512000 | I10: 36200 | J10: 475800 | L10: 0.92929688 | M10: 6
A11: 3 | B11: STEPHANIE LIZETH AQUINO HERRERA | F11: Dpto 1005 | G11: Crédito Hipotecario | H11: 480000 | I11: 24000 | J11: 456000 | L11: 0.95 | M11: 77
A12: 4 | B12: Sussan Yassmine Rubin Domínguez | F12: Dpto 805 | G12: Ahorro | H12: 470500 | I12: 42000 | J12: 428500 | L12: 0.91073326 | M12: 214
A13: 5 | B13: Marita Angeles Milla | F13: Dpto 1004 | G13: Ahorro | H13: 417700 | I13: 23770 | J13: 393930 | L13: 0.94309313 | M13: 46
A14: 6 | B14: PATROCINIO HUAMANI CUEVAS | F14: Dpto 503 | G14: Crédito Directo | H14: 660000 | I14: 500000 | J14: 160000 | L14: 0.24242424 | M14: 184
A15: 7 | B15: Gisella Isabel Martinez Andrade | F15: Dpto 304, Estc E 27 - D 21 | G15: Crédito Hipotecario | H15: 486500 | I15: 378650 | J15: 107850 | L15: 0.22168551 | M15: 58
A16: 8 | B16: PATROCINIO HUAMANI CUEVAS | F16: Estc E 17 - D 12 | G16: Crédito Directo | H16: 52500 | I16: 5000 | J16: 47500 | L16: 0.9047619 | M16: 30
A17: 9 | B17: Lizet Lopez Paucar | F17: Estc E 22 | G17: Crédito Directo | H17: 47500 | I17: 3000 | J17: 44500 | L17: 0.93684211 | M17: 38
A18: 10 | B18: Elmo Calatayud Chumbes | F18: Estc E 13 - D 10 | G18: Crédito Directo | H18: 57800 | I18: 20000 | J18: 37800 | L18: 0.65397924 | M18: 31
A19: 11 | B19: Luis Alberto Ovalle Huamanguilla | F19: Estc E 37 - D 28 | G19: Crédito Directo | H19: 52000 | I19: 17000 | J19: 35000 | L19: 0.67307692 | M19: 61
A20: 12 | B20: Karina Cabanillas Correa | F20: Estc E 09 - D 06 | G20: Crédito Directo | H20: 52000 | I20: 31600 | J20: 20400 | L20: 0.39230769 | M20: 92
A21: 13 | B21: Gersom Juver Gonzalez Alfaro | F21: Estc E 25 - D 19 | G21: Crédito Directo | H21: 60400 | I21: 20400 | J21: 20000 | L21: 0.33112583 | M21: 0
A24: BEYOND | F24: DEUDA TOTAL | H24: 8403829.2 | J24: CLIENTE | L24: 31
A25: Rank | B25: Cliente | F25: Unidad | G25: Financiamiento | H25: Precio Venta | I25: Monto Cobrado | J25: Monto Deuda | L25: Tasa de Morosidad | M25: Días de atraso
A26: 1 | B26: RONALD ANTONIO TICONA ARONES | F26: Dpto 703, Dpto 704 | G26: Crédito Hipotecario | H26: 942700 | I26: 94270 | J26: 848430 | L26: 0.9 | M26: 123
A27: 2 | B27: Tania Jackeline Valladares Timana | F27: Dpto 1001 | G27: Ahorro | H27: 518500 | I27: 39725 | J27: 478775 | L27: 0.92338476 | M27: 242
A28: 3 | B28: Jimmy Luis Andrade Morveli | F28: Dpto 601 | G28: Crédito Hipotecario | H28: 470000 | I28: 3000 | J28: 467000 | L28: 0.99361702 | M28: 199
A29: 4 | B29: Tania Milagros Cotrina Vara | F29: Dpto 205 | G29: Ahorro | H29: 577000 | I29: 120000 | J29: 457000 | L29: 0.79202773 | M29: 61
A30: 5 | B30: Leidy Lucero Espíritu Zabarburu | F30: Dpto 303 | G30: Ahorro | H30: 458000 | I30: 22900 | J30: 435100 | L30: 0.95 | M30: 31
A31: 6 | B31: Francesca Giuliana Ramos Ortiz | F31: Dpto 501, Estc E 14 - D 12 | G31: Ahorro | H31: 524500 | I31: 104900 | J31: 419600 | L31: 0.8 | M31: 61
A32: 7 | B32: Dolores Lissett Castillo Diaz | F32: Dpto 701, Estc E 17 | G32: Ahorro | H32: 521800 | I32: 104360 | J32: 417440 | L32: 0.8 | M32: 67
A33: 8 | B33: Juana Mercedes Moran Peralta | F33: Dpto 404 | G33: Ahorro | H33: 460000 | I33: 46000 | J33: 414000 | L33: 0.9 | M33: 13
A34: 9 | B34: Ronald José Claudio Ramírez | F34: Dpto 504, Estc E 07 | G34: Ahorro | H34: 510000 | I34: 102000 | J34: 408000 | L34: 0.8 | M34: 0
A35: 10 | B35: Jhoully Kattherine Moreno Saavedra | F35: Dpto 204 | G35: Crédito Hipotecario | H35: 450000 | I35: 45000 | J35: 405000 | L35: 0.9 | M35: 92
A36: 11 | B36: ERICK RAUL BEDOYA BACA | F36: Dpto 503 | G36: Crédito Hipotecario | H36: 470000 | I36: 70500 | J36: 399500 | L36: 0.85 | M36: 183
A37: 12 | B37: Mayra Andrea Montenegro Gomez | F37: Dpto 605 | G37: Crédito Hipotecario | H37: 495000 | I37: 99000 | J37: 396000 | L37: 0.8 | M37: 61
... A61: 36 | B61: Elizabeth Bertha Fierro Cancho | F61: Estc E 26 - D 17 | G61: Crédito Directo | H61: 51000 | I61: 19000 | J61: 3000 | L61: 0.058823529 | M61: 0
A64: VENECIA | F64: DEUDA TOTAL | H64: 1903965.9 | J64: CLIENTE | L64: 10
A65: Rank | B65: Cliente | F65: Unidad | G65: Financiamiento | H65: Precio Venta | I65: Monto Cobrado | J65: Monto Deuda | L65: Tasa de Morosidad | M65: Días de atraso
A66: 1 | B66: Ubaldo Yovera Puruguay | F66: Dpto 402 | G66: Ahorro | H66: 623000 | I66: 10000 | J66: 613000 | L66: 0.98394864 | M66: 36
A67: 2 | B67: Irma Paulina Palomino Huaman | F67: Dpto 701 | G67: Ahorro | H67: 561000 | I67: 21900 | J67: 539100 | L67: 0.96096257 | M67: 30
A68: 3 | B68: Mariela Gabriela Zapata Santivañez | F68: Dpto 205, Estc E 20 | G68: Crédito Hipotecario | H68: 432800 | I68: 86560 | J68: 346240 | L68: 0.8 | M68: 31
A69: 4 | B69: Rocio Chuquimango Valencia | F69: Dpto 602, Estc E 24 - D 5 | G69: Crédito Directo | H69: 624000 | I69: 79800 | J69: 180200.01 | L69: 0.28878207 | M69: 46
A70: 5 | B70: Carlos La Cruz Crespo | F70: Dpto 204, Estc E 14 - D 4 | G70: Crédito Directo | H70: 485800 | I70: 387320 | J70: 98480 | L70: 0.20271717 | M70: 0
...

Sheet Reporte_Cliente
A1: REPORTE DE COBRANZAS POR CLIENTE
A4: Rank | B4: Cliente | E4: Proyecto | G4: Tipo de Financiamiento | I4: Monto Vendido | K4: Deuda | M4: Días Atrasados | N4: Unidad Inmobiliaria | O4: Tasa de Morosidad
A5: 1 | B5: RONALD ANTONIO TICONA ARONES | E5: Beyond | G5: Crédito Hipotecario | I5: 942700 | K5: 848430 | M5: 123 | N5: Dpto 703, Dpto 704 | O5: 0.9
A6: 2 | B6: Ubaldo Yovera Puruguay | E6: Venecia | G6: Ahorro | I6: 623000 | K6: 613000 | M6: 36 | N6: Dpto 402 | O6: 0.98394864
A7: 3 | B7: Irma Paulina Palomino Huaman | E7: Venecia | G7: Ahorro | I7: 561000 | K7: 539100 | M7: 30 | N7: Dpto 701 | O7: 0.96096257
A8: 4 | B8: katherine Neyra Alor Neyra | E8: Prada | G8: Crédito Hipotecario | I8: 535000 | K8: 532000 | M8: 93 | N8: Dpto 405, Estc E 35 - D 27 | O8: 0.99439252
A9: 5 | B9: Tania Jackeline Valladares Timana | E9: Beyond | G9: Ahorro | I9: 518500 | K9: 478775 | M9: 242 | N9: Dpto 1001 | O9: 0.92338476
A10: 6 | B10: RODRIGO SANDRO CARDENAS BULLON | E10: Prada | G10: Ahorro | I10: 512000 | K10: 475800 | M10: 6 | N10: Dpto 402, Estc E 46 - D 35 | O10: 0.92929688
A11: 7 | B11: Jimmy Luis Andrade Morveli | E11: Beyond | G11: Crédito Hipotecario | I11: 470000 | K11: 467000 | M11: 199 | N11: Dpto 601 | O11: 0.99361702
A12: 8 | B12: Tania Milagros Cotrina Vara | E12: Beyond | G12: Ahorro | I12: 577000 | K12: 457000 | M12: 61 | N12: Dpto 205 | O12: 0.79202773
A13: 9 | B13: STEPHANIE LIZETH AQUINO HERRERA | E13: Prada | G13: Crédito Hipotecario | I13: 480000 | K13: 456000 | M13: 77 | N13: Dpto 1005 | O13: 0.95
A14: 10 | B14: Leidy Lucero Espíritu Zabarburu | E14: Beyond | G14: Ahorro | I14: 458000 | K14: 435100 | M14: 31 | N14: Dpto 303 | O14: 0.95
A15: 11 | B15: Sussan Yassmine Rubin Domínguez | E15: Prada | G15: Ahorro | I15: 470500 | K15: 428500 | M15: 214 | N15: Dpto 805 | O15: 0.91073326
A16: 12 | B16: Francesca Giuliana Ramos Ortiz | E16: Beyond | G16: Ahorro | I16: 524500 | K16: 419600 | M16: 61 | N16: Dpto 501, Estc E 14 - D 12 | O16: 0.8
... A64: 60 | B64: Evelyn Arciela Leon Estela | E64: Venecia | G64: Crédito Directo | I64: 48500 | K64: 1940 | M64: 0 | N64: Estc E 04 | O64: 0.04

Sheet Base_Cobranzas
A1: Proyecto | B1: Etapa | C1: Tipo_Construccion_1 | D1: Nombre_Tipo_Construccion_1 | E1: TipoInmueble_1 | F1: NroInmueble_1 | G1: PrecioLista_1 | H1: PrecioVenta_1 | I1: Tipo_Construccion_2 | J1: Nombre_Tipo_Construccion_2 | K1: TipoInmueble_2 | L1: NroInmueble_2 | M1: PrecioLista_2 | N1: PrecioVenta_2 | O1: Tipo_Construccion_3 | P1: Nombre_Tipo_Construccion_3 | Q1: TipoInmueble_3 | R1: NroInmueble_3 | S1: PrecioLista_3 | T1: PrecioVenta_3 | U1: Tipo_Construccion_4 | V1: Nombre_Tipo_Construccion_4 | W1: TipoInmueble_4 | X1: NroInmueble_4 | Y1: PrecioLista_4 | Z1: PrecioVenta_4 | AA1: Nombres_Titular | AB1: NroDocumento | AC1: Direccion | AD1: TelefonoCasa | AE1: TelefonoCelular | AF1: CorreoElectronico | AG1: Provincia | AH1: Distrito | AI1: Fecha_Programada | AJ1: FechaPago | AK1: Tipo_Cuota | AL1: Nro_Cuota | AM1: Capital | AN1: Intereses | AO1: GastosAdministrativos | AP1: Monto_Cuota | AQ1: Monto_Cuota_Pagado | AR1: SaldoPorPagarCuota | AS1: MontoMora | AT1: TipoFinanciamiento | AU1: Entidad_Financiera | AV1: Nro_Cuenta | AW1: Medio_Pago | AX1: Nro_Documento | AY1: Nro_Operacion | AZ1: Verificado | BA1: OrigenFondo | BB1: TipoCambio | BC1: Estado | BD1: Estado_Letra | BE1: Ubicación_Letra | BF1: Casuistica_Cuota | BG1: Accio_Cuota | BH1: FechaPromesa | BI1: ValorCompromiso | BJ1: Porcentaje | BK1: Comentario_Cuota | BL1: Fecha_Modificiacion_Seguimiento | BM1: Usuario_Modificiacion_Seguimiento | BN1: Doc_Adjunto | BO1: FechaOperacionComercial | BP1: Asesor_Comercial | BQ1: Asesor_Banco | BR1: Correlativo | BS1: Fecha_Registro_Pago_Cargado | BT1: ComisionPago | BU1: IdCotizacion | BV1: Doc_Contable | BW1: Monto_EstadoCuenta | BX1: Archivo_Origen | BY1: Anio_Descarga | BZ1: Fecha_Inicio_Reporte | CA1: Fecha_Fin_Reporte
A2: RESIDENCIAL PRADA | B2: Etapa 1 | C2: Edificio | D2: A | E2: Estacionamiento | F2: E 14 - D 11 | G2: 56300 | H2: 56300 | AA2: Ayleen Katia Messarina Rios | AB2: 70512701 | AC2: Departamento 101 Urbanización Santa Rosa de Surco etapa 2 Mz D Lt 23 | AD2: 978722675 | AE2: 978722675 | AF2: ayleen30mr@gmail.com | AG2: LIMA | AH2: SANTIAGO DE SURCO | AI2: 45628 | AJ2: 45628 | AK2: SEPARACION | AL2: 1 | AM2: 3000 | AN2: 0 | AO2: 0 | AP2: 3000 | AQ2: 3000 | AR2: 0 | AS2: 0 | AT2: Crédito Directo | AU2: Scotiabank Perú | AV2: 000-2768484 | AW2: TRANSFERENCIA BANCARIA | AY2: 000001100000012 | AZ2: Si | BB2: 4 | BC2: CANCELADO | BN2: Si | BO2: 45748.63 | BP2: Magaly Guevara Perez | BR2: 56 | BS2: 28/06/2026 21:22 | BT2: 0 | BX2: Cobranzas_2024.csv | BY2: 2024 | BZ2: 01/01/2024 | CA2: 30/09/2031
A3: RESIDENCIAL PRADA | B3: Etapa 1 | C3: Edificio | D3: A | E3: Estacionamiento | F3: E 14 - D 11 | G3: 56300 | H3: 56300 | AA3: Ayleen Katia Messarina Rios | AB3: 70512701 | AC3: Departamento 101 Urbanización Santa Rosa de Surco etapa 2 Mz D Lt 23 | AD3: 978722675 | AE3: 978722675 | AF3: ayleen30mr@gmail.com | AG3: LIMA | AH3: SANTIAGO DE SURCO | AI3: 45628 | AJ3: 45628 | AK3: CUOTA INICIAL | AL3: 1 | AM3: 7000 | AN3: 0 | AO3: 0 | AP3: 7000 | AQ3: 7000 | AR3: 0 | AS3: 0 | AT3: Crédito Directo | AU3: Scotiabank Perú | AV3: 000-2768484 | AW3: TRANSFERENCIA BANCARIA | AY3: 000001100000012 | AZ3: Si | BB3: 4 | BC3: CANCELADO | BN3: Si | BO3: 45748.63 | BP3: Magaly Guevara Perez | BR3: 56 | BS3: 28/06/2026 21:22 | BT3: 0 | BX3: Cobranzas_2024.csv | BY3: 2024 | BZ3: 01/01/2024 | CA3: 30/09/2031
A4: RESIDENCIAL PRADA | B4: Etapa 1 | C4: Edificio | D4: A | E4: Departamento | F4: 302 | G4: 435500 | H4: 435500 | AA4: Cristhiam Ortiz Angeles | AB4: 45110882 | AC4: Av. Olavegoya 1879 departamento 301 | AD4: 992532732 | AE4: 992532732 | AF4: Cristhian4520@gmail.com | AG4: LIMA | AH4: JESUS MARIA | AI4: 45473 | AJ4: 45473 | AK4: SEPARACION | AL4: 1 | AM4: 3000 | AN4: 0 | AO4: 0 | AP4: 3000 | AQ4: 3000 | AR4: 0 | AS4: 0 | AT4: Crédito Hipotecario | AU4: Scotiabank Perú | AV4: 000-2768484 | AW4: TRANSFERENCIA BANCARIA | AX4: 45110882 | AY4: 01226077 | AZ4: No | BA4: NO PRECISA | BB4: 4 | BC4: CANCELADO | BN4: Si | BO4: 45499.613 | BP4: Kenny Salazar S | BR4: 34 | BS4: 02/06/2026 15:34 | BT4: 0 | BX4: Cobranzas_2024.csv | BY4: 2024 | BZ4: 01/01/2024 | CA4: 30/09/2031
A5: RESIDENCIAL PRADA | B5: Etapa 1 | C5: Edificio | D5: A | E5: Departamento | F5: 302 | G5: 435500 | H5: 435500 | AA5: Cristhiam Ortiz Angeles | AB5: 45110882 | AC5: Av. Olavegoya 1879 departamento 301 | AD5: 992532732 | AE5: 992532732 | AF5: Cristhian4520@gmail.com | AG5: LIMA | AH5: JESUS MARIA | AI5: 45499 | AJ5: 45499 | AK5: CUOTA INICIAL | AL5: 1 | AM5: 20000 | AN5: 0 | AO5: 0 | AP5: 20000 | AQ5: 20000 | AR5: 0 | AS5: 0 | AT5: Crédito Hipotecario | AU5: Scotiabank Perú | AV5: 000-2768484 | AW5: CHEQUE DE GERENCIA | AX5: 45110882 | AY5: 162515191002194000000022290 | AZ5: Si | BA5: NO PRECISA | BB5: 4 | BC5: CANCELADO | BN5: Si | BO5: 45499.613 | BP5: Kenny Salazar S | BR5: 34 | BS5: 04/06/2026 14:01 | BT5: 0 | BX5: Cobranzas_2024.csv | BY5: 2024 | BZ5: 01/01/2024 | CA5: 30/09/2031
A6: RESIDENCIAL PRADA | B6: Etapa 1 | C6: Edificio | D6: A | E6: Departamento | F6: 302 | G6: 435500 | H6: 435500 | AA6: Cristhiam Ortiz Angeles | AB6: 45110882 | AC6: Av. Olavegoya 1879 departamento 301 | AD6: 992532732 | AE6: 992532732 | AF6: Cristhian4520@gmail.com | AG6: LIMA | AH6: JESUS MARIA | AI6: 45534 | AJ6: 45538 | AK6: CUOTA INICIAL | AL6: 2 | AM6: 8775 | AN6: 0 | AO6: 0 | AP6: 8775 | AQ6: 8775 | AR6: 0 | AS6: 0 | AT6: Crédito Hipotecario | AU6: Scotiabank Perú | AV6: 000-2768484 | AW6: TRANSFERENCIA BANCARIA | AY6: U26966 | AZ6: No | BB6: 4 | BC6: CANCELADO | BN6: Si | BO6: 45499.613 | BP6: Kenny Salazar S | BR6: 34 | BS6: 07/07/2026 08:47 | BT6: 0 | BX6: Cobranzas_2024.csv | BY6: 2024 | BZ6: 01/01/2024 | CA6: 30/09/2031
A7: RESIDENCIAL PRADA | B7: Etapa 1 | C7: Edificio | D7: A | E7: Departamento | F7: 302 | G7: 435500 | H7: 435500 | AA7: Cristhiam Ortiz Angeles | AB7: 45110882 | AC7: Av. Olavegoya 1879 departamento 301 | AD7: 992532732 | AE7: 992532732 | AF7: Cristhian4520@gmail.com | AG7: LIMA | AH7: JESUS MARIA | AI7: 45565 | AJ7: 45538 | AK7: CUOTA INICIAL | AL7: 3 | AM7: 0 | AN7: 0 | AO7: 0 | AP7: 11775 | AQ7: 1225 | AR7: 0 | AS7: 0 | AT7: Crédito Hipotecario | AU7: Scotiabank Perú | AV7: 000-2768484 | AW7: TRANSFERENCIA BANCARIA | AY7: U26966 | AZ7: No | BB7: 4 | BC7: CANCELADO | BN7: Si | BO7: 45499.613 | BP7: Kenny Salazar S | BR7: 34 | BS7: 07/07/2026 08:47 | BT7: 0 | BX7: Cobranzas_2024.csv | BY7: 2024 | BZ7: 01/01/2024 | CA7: 30/09/2031
A8: RESIDENCIAL PRADA | B8: Etapa 1 | C8: Edificio | D8: A | E8: Departamento | F8: 302 | G8: 435500 | H8: 435500 | AA8: Cristhiam Ortiz Angeles | AB8: 45110882 | AC8: Av. Olavegoya 1879 departamento 301 | AD8: 992532732 | AE8: 992532732 | AF8: Cristhian4520@gmail.com | AG8: LIMA | AH8: JESUS MARIA | AI8: 45565 | AJ8: 45569 | AK8: CUOTA INICIAL | AL8: 3 | AM8: 0 | AN8: 0 | AO8: 0 | AP8: 0 | AQ8: 10000 | AR8: 0 | AS8: 0 | AT8: Crédito Hipotecario | AU8: Scotiabank Perú | AV8: 000-2768484 | AW8: TRANSFERENCIA BANCARIA | AY8: U27618 | AZ8: No | BB8: 4 | BC8: CANCELADO | BN8: Si | BO8: 45499.613 | BP8: Kenny Salazar S | BR8: 34 | BS8: 07/07/2026 08:52 | BT8: 0 | BX8: Cobranzas_2024.csv | BY8: 2024 | BZ8: 01/01/2024 | CA8: 30/09/2031
A9: RESIDENCIAL PRADA | B9: Etapa 1 | C9: Edificio | D9: A | E9: Departamento | F9: 302 | G9: 435500 | H9: 435500 | AA9: Cristhiam Ortiz Angeles | AB9: 45110882 | AC9: Av. Olavegoya 1879 departamento 301 | AD9: 992532732 | AE9: 992532732 | AF9: Cristhian4520@gmail.com | AG9: LIMA | AH9: JESUS MARIA | AI9: 45565 | AJ9: 45693 | AK9: CUOTA INICIAL | AL9: 3 | AM9: 11775 | AN9: 0 | AO9: 0 | AP9: 0 | AQ9: 550 | AR9: 0 | AS9: 0 | AT9: Crédito Hipotecario | AU9: Scotiabank Perú | AV9: 000-2768484 | AW9: TRANSFERENCIA BANCARIA | AY9: U28731 | AZ9: No | BB9: 4 | BC9: CANCELADO | BN9: Si | BO9: 45499.613 | BP9: Kenny Salazar S | BR9: 34 | BS9: 07/07/2026 08:56 | BT9: 0 | BX9: Cobranzas_2024.csv | BY9: 2024 | BZ9: 01/01/2024 | CA9: 30/09/2031
A10: RESIDENCIAL PRADA | B10: Etapa 1 | C10: Edificio | D10: A | E10: Departamento | F10: 302 | G10: 435500 | H10: 435500 | AA10: Cristhiam Ortiz Angeles | AB10: 45110882 | AC10: Av. Olavegoya 1879 departamento 301 | AD10: 992532732 | AE10: 992532732 | AF10: Cristhian4520@gmail.com | AG10: LIMA | AH10: JESUS MARIA | AI10: 45656 | AJ10: 45693 | AK10: CUOTA INICIAL | AL10: 4 | AM10: 21000 | AN10: 0 | AO10: 0 | AP10: 21000 | AQ10: 21000 | AR10: 0 | AS10: 0 | AT10: Crédito Hipotecario | AU10: Scotiabank Perú | AV10: 000-2768484 | AW10: TRANSFERENCIA BANCARIA | AY10: U28731 | AZ10: No | BB10: 4 | BC10: CANCELADO | BN10: Si | BO10: 45499.613 | BP10: Kenny Salazar S | BR10: 34 | BS10: 07/07/2026 08:56 | BT10: 0 | BX10: Cobranzas_2024.csv | BY10: 2024 | BZ10: 01/01/2024 | CA10: 30/09/2031
A11: RESIDENCIAL BEYOND | B11: Etapa 1 | C11: Edificio | D11: A | E11: Departamento | F11: 505 | G11: 532100 | H11: 500000 | I11: Edificio | J11: A | K11: Estacionamiento | L11: E 05 | M11: 45600 | N11: 45600 | O11: Edificio | P11: A | Q11: Depósito | R11: D 05 | S11: 15900 | T11: 15900 | AA11: Dante Enrique Segura Florian | AB11: 45587286 | AC11: 1845 San Andres Dr Pitsburg CA 94565 - San Francisco | AD11: 0 | AE11: +15103330517 | AF11: d.segura@uaa.edu | AI11: 45368 | AJ11: 45368 | AK11: SEPARACION | AL11: 1 | AM11: 3000 | AN11: 0 | AO11: 0 | AP11: 3000 | AQ11: 3000 | AR11: 0 | AS11: 0 | AT11: Crédito Directo | AU11: Banco de Credito del Perú | AV11: 194-7325779-0-65 | AW11: TRANSFERENCIA BANCARIA | AY11: 7844655595634 | AZ11: No | BB11: 4 | BC11: CANCELADO | BN11: Si | BO11: 45386.403 | BP11: Carla Michue M | BR11: 35 | BS11: 25/05/2026 17:28 | BT11: 0 | BX11: Cobranzas_2024.csv | BY11: 2024 | BZ11: 01/01/2024 | CA11: 30/09/2031
A12: RESIDENCIAL PRADA | B12: Etapa 1 | C12: Edificio | D12: A | E12: Departamento | F12: 703 | G12: 654000 | H12: 654000 | I12: Edificio | J12: A | K12: Estacionamiento | L12: E 06 - D 04 | M12: 57500 | N12: 57500 | AA12: David Edgar Valencia Cordova | AB12: 41844906 | AC12: P. Joven Año Nuevo Jr. Montero Rosas 860 | AD12: 991846561 | AE12: 991846561 | AF12: davico29@gmail.com | AG12: LIMA | AH12: COMAS | AI12: 45655 | AJ12: 45655 | AK12: SEPARACION | AL12: 1 | AM12: 3000 | AN12: 0 | AO12: 0 | AP12: 3000 | AQ12: 3000 | AR12: 0 | AS12: 0 | AT12: Crédito Hipotecario | AU12: Scotiabank Perú | AV12: 000-2768484 | AW12: TRANSFERENCIA BANCARIA | AX12: 41844906 | AY12: 00000082000000000 | AZ12: No | BA12: NO PRECISA | BB12: 4 | BC12: CANCELADO | BN12: Si | BO12: 45687.617 | BP12: Carla Michue M | BR12: 38 | BS12: 02/06/2026 18:05 | BT12: 0 | BX12: Cobranzas_2024.csv | BY12: 2024 | BZ12: 01/01/2024 | CA12: 30/09/2031
A13: RESIDENCIAL PRADA | B13: Etapa 1 | C13: Edificio | D13: A | E13: Departamento | F13: 205 | G13: 490000 | H13: 490000 | AA13: Elizabeth Rocio Urbina Ñañez | AB13: 71404863 | AC13: Av. Arequipa 2651 | AE13: 943921218 | AF13: elizabethurbina9624@gmail.com | AG13: LIMA | AH13: LINCE | AI13: 45620 | AJ13: 45620 | AK13: SEPARACION | AL13: 1 | AM13: 2000 | AN13: 0 | AO13: 0 | AP13: 2000 | AQ13: 2000 | AR13: 0 | AS13: 0 | AT13: Crédito Hipotecario | AU13: Scotiabank Perú | AV13: 000-2768484 | AW13: TRANSFERENCIA BANCARIA | AY13: FD893378 | AZ13: No | BB13: 4 | BC13: CANCELADO | BN13: Si | BO13: 45750.733 | BP13: Carla Michue M | BR13: 5 | BS13: 29/06/2026 21:44 | BT13: 0 | BX13: Cobranzas_2024.csv | BY13: 2024 | BZ13: 01/01/2024 | CA13: 30/09/2031
A14: RESIDENCIAL PRADA | B14: Etapa 1 | C14: Edificio | D14: A | E14: Departamento | F14: 101 | G14: 637000 | H14: 637000 | AA14: Elmo Calatayud Chumbes | AB14: 15580131 | AC14: Avenida Tomas Valles 1530 Block 14 departamento 204 | AD14: 955600933 | AE14: 955600933 | AF14: ec.calatayud@gmail.com | AG14: LIMA | AH14: LOS OLIVOS | AI14: 45595 | AJ14: 45595 | AK14: SEPARACION | AL14: 1 | AM14: 3000 | AN14: 0 | AO14: 0 | AP14: 3000 | AQ14: 3000 | AR14: 0 | AS14: 0 | AT14: Crédito Hipotecario | AU14: Scotiabank Perú | AV14: 000-2768484 | AW14: TRANSFERENCIA BANCARIA | AY14: 04797111 | AZ14: No | BB14: 4 | BC14: CANCELADO | BN14: Si | BO14: 45626.65 | BP14: Carla Michue M | BR14: 25 | BS14: 26/06/2026 14:52 | BT14: 0 | BX14: Cobranzas_2024.csv | BY14: 2024 | BZ14: 01/01/2024 | CA14: 30/09/2031
A15: RESIDENCIAL PRADA | B15: Etapa 1 | C15: Edificio | D15: A | E15: Departamento | F15: 101 | G15: 637000 | H15: 637000 | AA15: Elmo Calatayud Chumbes | AB15: 15580131 | AC15: Avenida Tomas Valles 1530 Block 14 departamento 204 | AD15: 955600933 | AE15: 955600933 | AF15: ec.calatayud@gmail.com | AG15: LIMA | AH15: LOS OLIVOS | AI15: 45626 | AJ15: 45626 | AK15: CUOTA INICIAL | AL15: 1 | AM15: 27000 | AN15: 0 | AO15: 0 | AP15: 27000 | AQ15: 27000 | AR15: 0 | AS15: 0 | AT15: Crédito Hipotecario | AU15: Scotiabank Perú | AV15: 000-2768484 | AW15: TRANSFERENCIA BANCARIA | AY15: 78446555266223 | AZ15: No | BB15: 4 | BC15: CANCELADO | BN15: Si | BO15: 45626.65 | BP15: Carla Michue M | BR15: 25 | BS15: 26/06/2026 14:53 | BT15: 0 | BX15: Cobranzas_2024.csv | BY15: 2024 | BZ15: 01/01/2024 | CA15: 30/09/2031
A16: RESIDENCIAL PRADA | B16: Etapa 1 | C16: Edificio | D16: A | E16: Departamento | F16: 101 | G16: 637000 | H16: 637000 | AA16: Elmo Calatayud Chumbes | AB16: 15580131 | AC16: Avenida Tomas Valles 1530 Block 14 departamento 204 | AD16: 955600933 | AE16: 955600933 | AF16: ec.calatayud@gmail.com | AG16: LIMA | AH16: LOS OLIVOS | AI16: 45626 | AJ16: 45626 | AK16: CUOTA INICIAL | AL16: 2 | AM16: 3000 | AN16: 0 | AO16: 0 | AP16: 3000 | AQ16: 3000 | AR16: 0 | AS16: 0 | AT16: Crédito Hipotecario | AU16: Scotiabank Perú | AV16: 000-2768484 | AW16: TRANSFERENCIA BANCARIA | AY16: 7844655544194 | AZ16: No | BB16: 4 | BC16: CANCELADO | BN16: Si | BO16: 45626.65 | BP16: Carla Michue M | BR16: 25 | BS16: 26/06/2026 14:53 | BT16: 0 | BX16: Cobranzas_2024.csv | BY16: 2024 | BZ16: 01/01/2024 | CA16: 30/09/2031
A17: RESIDENCIAL PRADA | B17: Etapa 1 | C17: Edificio | D17: A | E17: Departamento | F17: 101 | G17: 637000 | H17: 637000 | AA17: Elmo Calatayud Chumbes | AB17: 15580131 | AC17: Avenida Tomas Valles 1530 Block 14 departamento 204 | AD17: 955600933 | AE17: 955600933 | AF17: ec.calatayud@gmail.com | AG17: LIMA | AH17: LOS OLIVOS | AI17: 45656 | AJ17: 45656 | AK17: CUOTA INICIAL | AL17: 3 | AM17: 0 | AN17: 0 | AO17: 0 | AP17: 30700 | AQ17: 30000 | AR17: 0 | AS17: 0 | AT17: Crédito Hipotecario | AU17: Scotiabank Perú | AV17: 000-2768484 | AW17: TRANSFERENCIA BANCARIA | AY17: 7844655610530 | AZ17: No | BB17: 4 | BC17: CANCELADO | BN17: Si | BO17: 45626.65 | BP17: Carla Michue M | BR17: 25 | BS17: 26/06/2026 14:55 | BT17: 0 | BX17: Cobranzas_2024.csv | BY17: 2024 | BZ17: 01/01/2024 | CA17: 30/09/2031
A18: RESIDENCIAL PRADA | B18: Etapa 1 | C18: Edificio | D18: A | E18: Departamento | F18: 101 | G18: 637000 | H18: 637000 | AA18: Elmo Calatayud Chumbes | AB18: 15580131 | AC18: Avenida Tomas Valles 1530 Block 14 departamento 204 | AD18: 955600933 | AE18: 955600933 | AF18: ec.calatayud@gmail.com | AG18: LIMA | AH18: LOS OLIVOS | AI18: 45656 | AJ18: 45656 | AK18: CUOTA INICIAL | AL18: 3 | AM18: 30700 | AN18: 0 | AO18: 0 | AP18: 0 | AQ18: 700 | AR18: 0 | AS18: 0 | AT18: Crédito Hipotecario | AU18: Scotiabank Perú | AV18: 000-2768484 | AW18: TRANSFERENCIA BANCARIA | AY18: 7844655610860 | AZ18: No | BB18: 4 | BC18: CANCELADO | BN18: Si | BO18: 45626.65 | BP18: Carla Michue M | BR18: 25 | BS18: 26/06/2026 14:56 | BT18: 0 | BX18: Cobranzas_2024.csv | BY18: 2024 | BZ18: 01/01/2024 | CA18: 30/09/2031
A19: RESIDENCIAL PRADA | B19: Etapa 1 | C19: Edificio | D19: A | E19: Departamento | F19: 203 | G19: 654000 | H19: 654000 | I19: Edificio | J19: A | K19: Estacionamiento | L19: E 12 - D 09 | M19: 56300 | N19: 56300 | AA19: Gilberto Videla Flores | AB19: 06571347 | AC19: Mz D Lt 7 Urb. La Estrella | AE19: 969742622 | AF19: gvidelaf@gmail.com | AG19: LIMA | AH19: LOS OLIVOS | AI19: 45535 | AJ19: 45535 | AK19: SEPARACION | AL19: 1 | AM19: 3000 | AN19: 0 | AO19: 0 | AP19: 3000 | AQ19: 3000 | AR19: 0 | AS19: 0 | AT19: Crédito Directo | AU19: Scotiabank Perú | AV19: 000-2768484 | AW19: POS VISA | AX19: 06571347 | AY19: 0059 | AZ19: No | BA19: NO PRECISA | BB19: 1 | BC19: CANCELADO | BN19: Si | BO19: 45539.381 | BP19: Carla Michue M | BR19: 24 | BS19: 29/05/2026 12:21 | BT19: 0 | BX19: Cobranzas_2024.csv | BY19: 2024 | BZ19: 01/01/2024 | CA19: 30/09/2031
A20: RESIDENCIAL PRADA | B20: Etapa 1 | C20: Edificio | D20: A | E20: Departamento | F20: 203 | G20: 654000 | H20: 654000 | I20: Edificio | J20: A | K20: Estacionamiento | L20: E 12 - D 09 | M20: 56300 | N20: 56300 | AA20: Gilberto Videla Flores | AB20: 06571347 | AC20: Mz D Lt 7 Urb. La Estrella | AE20: 969742622 | AF20: gvidelaf@gmail.com | AG20: LIMA | AH20: LOS OLIVOS | AI20: 45539 | AJ20: 45539 | AK20: CUOTA INICIAL | AL20: 2 | AM20: 281120 | AN20: 0 | AO20: 0 | AP20: 281120 | AQ20: 281120 | AR20: 0 | AS20: 0 | AT20: Crédito Directo | AU20: Scotiabank Perú | AV20: 000-2768484 | AW20: TRANSFERENCIA BANCARIA | AY20: 0953413 | AZ20: No | BB20: 4 | BC20: CANCELADO | BN20: Si | BO20: 45539.381 | BP20: Carla Michue M | BR20: 24 | BS20: 30/06/2026 16:33 | BT20: 0 | BX20: Cobranzas_2024.csv | BY20: 2024 | BZ20: 01/01/2024 | CA20: 30/09/2031
A21: RESIDENCIAL PRADA | B21: Etapa 1 | C21: Edificio | D21: A | E21: Departamento | F21: 203 | G21: 654000 | H21: 654000 | I21: Edificio | J21: A | K21: Estacionamiento | L21: E 12 - D 09 | M21: 56300 | N21: 56300 | AA21: Gilberto Videla Flores | AB21: 06571347 | AC21: Mz D Lt 7 Urb. La Estrella | AE21: 969742622 | AF21: gvidelaf@gmail.com | AG21: LIMA | AH21: LOS OLIVOS | AI21: 45559 | AJ21: 45559 | AK21: SALDO FINANCIAR | AL21: 3 | AM21: 248605 | AN21: 0 | AO21: 0 | AP21: 248605 | AQ21: 248605 | AR21: 0 | AS21: 0 | AT21: Crédito Directo | AU21: Scotiabank Perú | AV21: 000-2768484 | AW21: TRANSFERENCIA BANCARIA | AY21: 0036913 | AZ21: No | BB21: 4 | BC21: CANCELADO | BN21: Si | BO21: 45539.381 | BP21: Carla Michue M | BR21: 24 | BS21: 30/06/2026 16:48 | BT21: 0 | BX21: Cobranzas_2024.csv | BY21: 2024 | BZ21: 01/01/2024 | CA21: 30/09/2031
A22: RESIDENCIAL PRADA | B22: Etapa 1 | C22: Edificio | D22: A | E22: Departamento | F22: 104 | G22: 609100 | H22: 609100 | I22: Edificio | J22: A | K22: Estacionamiento | L22: E 26 - D 20 | M22: 64600 | N22: 64600 | AA22: Gilda Victoria Sampi González | AB22: 43636501 | AC22: Av. Brasil 863 departamento 702-A | AD22: 966422784 | AE22: 966422784 | AF22: victoria.sampi@gmail.com | AG22: LIMA | AH22: JESUS MARIA | AI22: 45494 | AJ22: 45494 | AK22: SEPARACION | AL22: 1 | AM22: 3000 | AN22: 0 | AO22: 0 | AP22: 3000 | AQ22: 3000 | AR22: 0 | AS22: 0 | AT22: Crédito Hipotecario | AU22: Scotiabank Perú | AV22: 000-2768484 | AW22: TRANSFERENCIA BANCARIA | AX22: 43636501 | AY22: 00998929 | AZ22: No | BA22: NO PRECISA | BB22: 4 | BC22: CANCELADO | BN22: Si | BO22: 45537.593 | BP22: Kenny Salazar S | BR22: 32 | BS22: 02/06/2026 14:50 | BT22: 0 | BX22: Cobranzas_2024.csv | BY22: 2024 | BZ22: 01/01/2024 | CA22: 30/09/2031
A23: RESIDENCIAL PRADA | B23: Etapa 1 | C23: Edificio | D23: A | E23: Departamento | F23: 104 | G23: 609100 | H23: 609100 | I23: Edificio | J23: A | K23: Estacionamiento | L23: E 26 - D 20 | M23: 64600 | N23: 64600 | AA23: Gilda Victoria Sampi González | AB23: 43636501 | AC23: Av. Brasil 863 departamento 702-A | AD23: 966422784 | AE23: 966422784 | AF23: victoria.sampi@gmail.com | AG23: LIMA | AH23: JESUS MARIA | AI23: 45537 | AJ23: 45537 | AK23: CUOTA INICIAL | AL23: 1 | AM23: 134740 | AN23: 0 | AO23: 0 | AP23: 134740 | AQ23: 134740 | AR23: 0 | AS23: 0 | AT23: Crédito Hipotecario | AU23: Scotiabank Perú | AV23: 000-2768484 | AW23: TRANSFERENCIA BANCARIA | AX23: 43636501 | AY23: 009107870 | AZ23: No | BA23: NO PRECISA | BB23: 4 | BC23: CANCELADO | BN23: Si | BO23: 45537.593 | BP23: Kenny Salazar S | BR23: 32 | BS23: 04/06/2026 09:52 | BT23: 0 | BX23: Cobranzas_2024.csv | BY23: 2024 | BZ23: 01/01/2024 | CA23: 30/09/2031
A24: RESIDENCIAL PRADA | B24: Etapa 1 | C24: Edificio | D24: A | E24: Departamento | F24: 605 | G24: 501000 | H24: 501000 | I24: Edificio | J24: A | K24: Estacionamiento | L24: E 07 - D 05 | M24: 57300 | N24: 57300 | AA24: Jose Humberto Pehovaz Diez | AB24: 49073756 | AC24: - | AE24: 952256518 | AF24: josehp99@gmail.com | AG24: LIMA | AH24: MAGDALENA DEL MAR | AI24: 45338 | AJ24: 45698 | AK24: SEPARACION | AL24: 1 | AM24: 3000 | AN24: 0 | AO24: 0 | AP24: 3000 | AQ24: 3000 | AR24: 0 | AS24: 0 | AT24: Crédito Hipotecario | AU24: Scotiabank Perú | AV24: 000-2768484 | AW24: TRANSFERENCIA BANCARIA | AX24: 49073756 | AY24: 7844655534521 | AZ24: No | BA24: NO PRECISA | BB24: 1 | BC24: CANCELADO | BN24: Si | BO24: 45709.697 | BP24: Carla Michue M | BR24: 10 | BS24: 29/05/2026 12:21 | BT24: 0 | BX24: Cobranzas_2024.csv | BY24: 2024 | BZ24: 01/01/2024 | CA24: 30/09/2031
A25: RESIDENCIAL PRADA | B25: Etapa 1 | C25: Edificio | D25: A | E25: Departamento | F25: 201 | G25: 622500 | H25: 622500 | AA25: Joseluis Gaspar Zapata Flores | AB25: 46730672 | AC25: Jr. Los Clavles 141 P. J El Progreso 1er Sector | AE25: 948041027 | AF25: jlzapata91@gmail.com | AG25: LIMA | AH25: CARABAYLLO | AI25: 45479 | AJ25: 45479 | AK25: CUOTA INICIAL | AL25: 1 | AM25: 3000 | AN25: 0 | AO25: 0 | AP25: 3000 | AQ25: 3000 | AR25: 0 | AS25: 0 | AT25: Ahorro | AU25: Scotiabank Perú | AV25: 000-2768484 | AW25: TRANSFERENCIA BANCARIA | AY25: 03343387 | AZ25: Si | BB25: 4 | BC25: CANCELADO | BN25: Si | BO25: 45488.655 | BP25: Carla Michue M | BR25: 6 | BS25: 29/06/2026 01:05 | BT25: 0 | BX25: Cobranzas_2024.csv | BY25: 2024 | BZ25: 01/01/2024 | CA25: 30/09/2031
A26: RESIDENCIAL PRADA | B26: Etapa 1 | C26: Edificio | D26: A | E26: Departamento | F26: 201 | G26: 622500 | H26: 622500 | AA26: Joseluis Gaspar Zapata Flores | AB26: 46730672 | AC26: Jr. Los Clavles 141 P. J El Progreso 1er Sector | AE26: 948041027 | AF26: jlzapata91@gmail.com | AG26: LIMA | AH26: CARABAYLLO | AI26: 45488 | AJ26: 45488 | AK26: CUOTA INICIAL | AL26: 2 | AM26: 20000 | AN26: 0 | AO26: 0 | AP26: 20000 | AQ26: 20000 | AR26: 0 | AS26: 0 | AT26: Ahorro | AU26: Scotiabank Perú | AV26: 000-2768484 | AW26: TRANSFERENCIA BANCARIA | AY26: 7844655656315 | AZ26: No | BB26: 4 | BC26: CANCELADO | BN26: Si | BO26: 45488.655 | BP26: Carla Michue M | BR26: 6 | BS26: 29/06/2026 01:06 | BT26: 0 | BX26: Cobranzas_2024.csv | BY26: 2024 | BZ26: 01/01/2024 | CA26: 30/09/2031
A27: RESIDENCIAL PRADA | B27: Etapa 1 | C27: Edificio | D27: A | E27: Departamento | F27: 201 | G27: 622500 | H27: 622500 | AA27: Joseluis Gaspar Zapata Flores | AB27: 46730672 | AC27: Jr. Los Clavles 141 P. J El Progreso 1er Sector | AE27: 948041027 | AF27: jlzapata91@gmail.com | AG27: LIMA | AH27: CARABAYLLO | AI27: 45656 | AJ27: 45722 | AK27: CUOTA INICIAL | AL27: 3 | AM27: 0 | AN27: 0 | AO27: 0 | AP27: 67000 | AQ27: 65000 | AR27: 0 | AS27: 0 | AT27: Ahorro | AU27: Scotiabank Perú | AV27: 000-2768484 | AW27: TRANSFERENCIA BANCARIA | AY27: u26563 | AZ27: No | BB27: 4 | BC27: CANCELADO | BN27: Si | BO27: 45488.655 | BP27: Carla Michue M | BR27: 6 | BS27: 29/06/2026 01:07 | BT27: 0 | BX27: Cobranzas_2024.csv | BY27: 2024 | BZ27: 01/01/2024 | CA27: 30/09/2031
A28: RESIDENCIAL PRADA | B28: Etapa 1 | C28: Edificio | D28: A | E28: Departamento | F28: 201 | G28: 622500 | H28: 622500 | AA28: Joseluis Gaspar Zapata Flores | AB28: 46730672 | AC28: Jr. Los Clavles 141 P. J El Progreso 1er Sector | AE28: 948041027 | AF28: jlzapata91@gmail.com | AG28: LIMA | AH28: CARABAYLLO | AI28: 45656 | AJ28: 45722 | AK28: CUOTA INICIAL | AL28: 3 | AM28: 67000 | AN28: 0 | AO28: 0 | AP28: 0 | AQ28: 2000 | AR28: 0 | AS28: 0 | AT28: Ahorro | AU28: Scotiabank Perú | AV28: 000-2768484 | AW28: TRANSFERENCIA BANCARIA | AY28: 7844655541508 | AZ28: No | BB28: 4 | BC28: CANCELADO | BN28: Si | BO28: 45488.655 | BP28: Carla Michue M | BR28: 6 | BS28: 29/06/2026 01:08 | BT28: 0 | BX28: Cobranzas_2024.csv | BY28: 2024 | BZ28: 01/01/2024 | CA28: 30/09/2031
A29: RESIDENCIAL PRADA | B29: Etapa 1 | C29: Edificio | D29: A | E29: Departamento | F29: 501 | G29: 612000 | H29: 612000 | AA29: Juan Carlos Ángeles Milla | AB29: 32403305 | AC29: Av. Miraflores 218 | AE29: 942097700 | AF29: Vidang72@hotmail.com | AG29: HUAYLAS | AH29: HUAYLAS | AI29: 45520 | AJ29: 45520 | AK29: SEPARACION | AL29: 1 | AM29: 3000 | AN29: 0 | AO29: 0 | AP29: 3000 | AQ29: 3000 | AR29: 0 | AS29: 0 | AT29: Ahorro | AU29: Scotiabank Perú | AV29: 000-2768484 | AW29: TRANSFERENCIA BANCARIA | AX29: 32403305 | AY29: 02431073 | AZ29: No | BA29: NO PRECISA | BB29: 1 | BC29: CANCELADO | BN29: Si | BO29: 45541.594 | BP29: Carla Michue M | BR29: 21 | BS29: 29/05/2026 12:21 | BT29: 0 | BX29: Cobranzas_2024.csv | BY29: 2024 | BZ29: 01/01/2024 | CA29: 30/09/2031
A30: RESIDENCIAL PRADA | B30: Etapa 1 | C30: Edificio | D30: A | E30: Departamento | F30: 501 | G30: 612000 | H30: 612000 | AA30: Juan Carlos Ángeles Milla | AB30: 32403305 | AC30: Av. Miraflores 218 | AE30: 942097700 | AF30: Vidang72@hotmail.com | AG30: HUAYLAS | AH30: HUAYLAS | AI30: 45541 | AJ30: 45541 | AK30: CUOTA INICIAL | AL30: 2 | AM30: 29500 | AN30: 0 | AO30: 0 | AP30: 29500 | AQ30: 29500 | AR30: 0 | AS30: 0 | AT30: Ahorro | AU30: Scotiabank Perú | AV30: 000-2768484 | AW30: TRANSFERENCIA BANCARIA | AX30: 32403305 | AY30: 0500010059 | AZ30: No | BA30: NO PRECISA | BB30: 1 | BC30: CANCELADO | BN30: Si | BO30: 45541.594 | BP30: Carla Michue M | BR30: 21 | BS30: 29/05/2026 12:21 | BT30: 0 | BX30: Cobranzas_2024.csv | BY30: 2024 | BZ30: 01/01/2024 | CA30: 30/09/2031
A31: RESIDENCIAL PRADA | B31: Etapa 1 | C31: Edificio | D31: A | E31: Departamento | F31: 403 | G31: 654000 | H31: 654000 | AA31: Liliana Lucila Luciano Claros | AB31: 15764694 | AC31: MZ M5 – Lt. 7 urb. Paseo del Mar | AE31: 982406857 | AF31: liliana31_micaela@hotmail.com | AG31: SANTA | AH31: NUEVO CHIMBOTE | AI31: 45586 | AJ31: 45586 | AK31: SEPARACION | AL31: 1 | AM31: 3000 | AN31: 0 | AO31: 0 | AP31: 3000 | AQ31: 3000 | AR31: 0 | AS31: 0 | AT31: Crédito Hipotecario | AU31: Scotiabank Perú | AV31: 000-2768484 | AW31: EFECTIVO | AX31: 15764694 | AY31: 0500010056 | AZ31: No | BA31: NO PRECISA | BB31: 1 | BC31: CANCELADO | BN31: Si | BO31: 45619.386 | BP31: Carla Michue M | BR31: 1 | BS31: 29/05/2026 12:20 | BT31: 0 | BX31: Cobranzas_2024.csv | BY31: 2024 | BZ31: 01/01/2024 | CA31: 30/09/2031
A32: RESIDENCIAL PRADA | B32: Etapa 1 | C32: Edificio | D32: A | E32: Departamento | F32: 403 | G32: 654000 | H32: 654000 | AA32: Liliana Lucila Luciano Claros | AB32: 15764694 | AC32: MZ M5 – Lt. 7 urb. Paseo del Mar | AE32: 982406857 | AF32: liliana31_micaela@hotmail.com | AG32: SANTA | AH32: NUEVO CHIMBOTE | AI32: 45619 | AJ32: 45619 | AK32: CUOTA INICIAL | AL32: 2 | AM32: 97800 | AN32: 0 | AO32: 0 | AP32: 97800 | AQ32: 97800 | AR32: 0 | AS32: 0 | AT32: Crédito Hipotecario | AU32: Scotiabank Perú | AV32: 000-2768484 | AW32: TRANSFERENCIA BANCARIA | AY32: 12007725 | AZ32: No | BB32: 4 | BC32: CANCELADO | BN32: Si | BO32: 45619.386 | BP32: Carla Michue M | BR32: 1 | BS32: 07/07/2026 09:30 | BT32: 0 | BX32: Cobranzas_2024.csv | BY32: 2024 | BZ32: 01/01/2024 | CA32: 30/09/2031
A33: RESIDENCIAL PRADA | B33: Etapa 1 | C33: Edificio | D33: A | E33: Departamento | F33: 403 | G33: 654000 | H33: 654000 | AA33: Liliana Lucila Luciano Claros | AB33: 15764694 | AC33: MZ M5 – Lt. 7 urb. Paseo del Mar | AE33: 982406857 | AF33: liliana31_micaela@hotmail.com | AG33: SANTA | AH33: NUEVO CHIMBOTE | AI33: 45631 | AJ33: 45631 | AK33: CUOTA INICIAL | AL33: 3 | AM33: 30000 | AN33: 0 | AO33: 0 | AP33: 30000 | AQ33: 30000 | AR33: 0 | AS33: 0 | AT33: Crédito Hipotecario | AU33: Scotiabank Perú | AV33: 000-2768484 | AW33: DEPOSITO EN CUENTA | AX33: 15764694 | AY33: 05000010069 | AZ33: No | BA33: NO PRECISA | BB33: 1 | BC33: CANCELADO | BN33: Si | BO33: 45619.386 | BP33: Carla Michue M | BR33: 1 | BS33: 29/05/2026 12:20 | BT33: 0 | BX33: Cobranzas_2024.csv | BY33: 2024 | BZ33: 01/01/2024 | CA33: 30/09/2031
A34: RESIDENCIAL PRADA | B34: Etapa 1 | C34: Edificio | D34: A | E34: Departamento | F34: 403 | G34: 654000 | H34: 654000 | AA34: Liliana Lucila Luciano Claros | AB34: 15764694 | AC34: MZ M5 – Lt. 7 urb. Paseo del Mar | AE34: 982406857 | AF34: liliana31_micaela@hotmail.com | AG34: SANTA | AH34: NUEVO CHIMBOTE | AI34: 45657 | AJ34: 45723 | AK34: SALDO FINANCIAR | AL34: 4 | AM34: 523200 | AN34: 0 | AO34: 0 | AP34: 523200 | AQ34: 523200 | AR34: 0 | AS34: 0 | AT34: Crédito Hipotecario | AU34: Scotiabank Perú | AV34: 000-2768484 | AW34: TRANSFERENCIA BANCARIA | AY34: 07032025 | AZ34: Si | BB34: 4 | BC34: CANCELADO | BN34: Si | BO34: 45619.386 | BP34: Carla Michue M | BR34: 1 | BS34: 07/07/2026 09:31 | BT34: 0 | BX34: Cobranzas_2024.csv | BY34: 2024 | BZ34: 01/01/2024 | CA34: 30/09/2031
A35: RESIDENCIAL PRADA | B35: Etapa 1 | C35: Edificio | D35: A | E35: Departamento | F35: 603 | G35: 654000 | H35: 654000 | AA35: Luis Alberto Ovalle Huamanguilla | AB35: 43953371 | AC35: JR. NAPO NRO. 821 | AE35: 992764943 | AF35: aovalle2212@gmail.com | AG35: LIMA | AH35: BREÑA | AI35: 45477 | AJ35: 45477 | AK35: SEPARACION | AL35: 1 | AM35: 3000 | AN35: 0 | AO35: 0 | AP35: 3000 | AQ35: 3000 | AR35: 0 | AS35: 0 | AT35: Ahorro | AU35: Scotiabank Perú | AV35: 000-2768484 | AW35: TRANSFERENCIA BANCARIA | AY35: 901866 | AZ35: No | BB35: 4 | BC35: CANCELADO | BN35: Si | BO35: 45567.694 | BP35: Carla Michue M | BR35: 11 | BS35: 07/07/2026 10:58 | BT35: 0 | BX35: Cobranzas_2024.csv | BY35: 2024 | BZ35: 01/01/2024 | CA35: 30/09/2031
A36: RESIDENCIAL PRADA | B36: Etapa 1 | C36: Edificio | D36: A | E36: Departamento | F36: 603 | G36: 654000 | H36: 654000 | AA36: Luis Alberto Ovalle Huamanguilla | AB36: 43953371 | AC36: JR. NAPO NRO. 821 | AE36: 992764943 | AF36: aovalle2212@gmail.com | AG36: LIMA | AH36: BREÑA | AI36: 45656 | AJ36: 45567 | AK36: SEPARACION | AL36: 5 | AM36: 5000 | AN36: 0 | AO36: 0 | AP36: 5000 | AQ36: 5000 | AR36: 0 | AS36: 0 | AT36: Ahorro | AU36: Scotiabank Perú | AV36: 000-2768484 | AW36: TRANSFERENCIA BANCARIA | AY36: 06056215 | AZ36: No | BB36: 4 | BC36: CANCELADO | BN36: Si | BO36: 45567.694 | BP36: Carla Michue M | BR36: 11 | BS36: 07/07/2026 11:03 | BT36: 0 | BX36: Cobranzas_2024.csv | BY36: 2024 | BZ36: 01/01/2024 | CA36: 30/09/2031
A37: RESIDENCIAL PRADA | B37: Etapa 1 | C37: Edificio | D37: A | E37: Departamento | F37: 603 | G37: 654000 | H37: 654000 | AA37: Luis Alberto Ovalle Huamanguilla | AB37: 43953371 | AC37: JR. NAPO NRO. 821 | AE37: 992764943 | AF37: aovalle2212@gmail.com | AG37: LIMA | AH37: BREÑA | AI37: 45656 | AJ37: 45567 | AK37: CUOTA INICIAL | AL37: 1 | AM37: 57400 | AN37: 0 | AO37: 0 | AP37: 57400 | AQ37: 20000 | AR37: 0 | AS37: 0 | AT37: Ahorro | AU37: Scotiabank Perú | AV37: 000-2768484 | AW37: TRANSFERENCIA BANCARIA | AY37: 06056215 | AZ37: No | BB37: 4 | BC37: CANCELADO | BN37: Si | BO37: 45567.694 | BP37: Carla Michue M | BR37: 11 | BS37: 07/07/2026 11:03 | BT37: 0 | BX37: Cobranzas_2024.csv | BY37: 2024 | BZ37: 01/01/2024 | CA37: 30/09/2031
A38: RESIDENCIAL PRADA | B38: Etapa 1 | C38: Edificio | D38: A | E38: Departamento | F38: 603 | G38: 654000 | H38: 654000 | AA38: Luis Alberto Ovalle Huamanguilla | AB38: 43953371 | AC38: JR. NAPO NRO. 821 | AE38: 992764943 | AF38: aovalle2212@gmail.com | AG38: LIMA | AH38: BREÑA | AI38: 45656 | AJ38: 45723 | AK38: CUOTA INICIAL | AL38: 1 | AM38: 0 | AN38: 0 | AO38: 0 | AP38: 0 | AQ38: 37400 | AR38: 0 | AS38: 0 | AT38: Ahorro | AU38: Scotiabank Perú | AV38: 000-2768484 | AW38: TRANSFERENCIA BANCARIA | AY38: U26926 | AZ38: No | BB38: 4 | BC38: CANCELADO | BN38: Si | BO38: 45567.694 | BP38: Carla Michue M | BR38: 11 | BS38: 07/07/2026 11:04 | BT38: 0 | BX38: Cobranzas_2024.csv | BY38: 2024 | BZ38: 01/01/2024 | CA38: 30/09/2031
A39: RESIDENCIAL PRADA | B39: Etapa 1 | C39: Edificio | D39: A | E39: Departamento | F39: 103 | G39: 520400 | H39: 520400 | AA39: Luis Eduardo Herrera Arrasco | AB39: 70656236 | AC39: Podesta Pescheira 273 - Pueblo Libre | AE39: 987782194 | AF39: luisherrarra19@gmail.com | AI39: 45578 | AJ39: 45578 | AK39: SEPARACION | AL39: 1 | AM39: 3000 | AN39: 0 | AO39: 0 | AP39: 3000 | AQ39: 3000 | AR39: 0 | AS39: 0 | AT39: Crédito Hipotecario | AU39: Scotiabank Perú | AV39: 000-2768484 | AW39: TRANSFERENCIA BANCARIA | AY39: 01871075 | AZ39: No | BB39: 4 | BC39: CANCELADO | BN39: Si | BO39: 45663.588 | BP39: Kenny Salazar S | BR39: 31 | BS39: 26/06/2026 17:22 | BT39: 0 | BX39: Cobranzas_2024.csv | BY39: 2024 | BZ39: 01/01/2024 | CA39: 30/09/2031
A40: RESIDENCIAL PRADA | B40: Etapa 1 | C40: Edificio | D40: A | E40: Departamento | F40: 202 | G40: 446900 | H40: 446900 | AA40: María Cristina Collazos Romero | AB40: 31676885 | AC40: Jr. Huandoy 242 | AD40: 969870030 | AE40: 969870030 | AF40: gerenciasnacks1@gmail.com | AG40: HUARAZ | AH40: HUARAZ | AI40: 45526 | AJ40: 45526 | AK40: SEPARACION | AL40: 1 | AM40: 3000 | AN40: 0 | AO40: 0 | AP40: 3000 | AQ40: 3000 | AR40: 0 | AS40: 0 | AT40: Crédito Hipotecario | AU40: Scotiabank Perú | AV40: 000-2768484 | AW40: TRANSFERENCIA BANCARIA | AX40: 31676885 | AY40: 0500010101 | AZ40: No | BA40: NO PRECISA | BB40: 4 | BC40: CANCELADO | BN40: Si | BO40: 45911.607 | BP40: Kenny Salazar S | BR40: 33 | BS40: 02/06/2026 15:10 | BT40: 0 | BX40: Cobranzas_2024.csv | BY40: 2024 | BZ40: 01/01/2024 | CA40: 30/09/2031
...

Sheet Prada
C5: REPORTE DE COBRANZAS
B6: Prada
C8: Vendido | F8: Cobranzas
C9: Monto | D9: Unidades | F9: Avance | G9: Cobrado | H9: Por Cobrar | I9: Vencido | J9: Tasa de Morosidad | K9: Clientes Morosos (unidades) | L9: Dias de Atraso (Promedio)
B11: Departamentos | C11: 25253600 | D11: 62 | F11: =IF(C11=0,0,G11/C11) | G11: =SUM(G12:G13) | H11: =SUM(H12:H13) | I11: =SUM(I12:I13) | J11: =IF(C11=0,0,I11/C11) | K11: 7 | L11: 90
B12: Departamento | C12: 16401100 | D12: 31 | F12: =IF(C12=0,0,G12/C12) | G12: =IFERROR(SUMPRODUCT(--ISNUMBER(SEARCH($B$6,'Base_Cobranzas'!$A$2:$A$1005)),--((--ISNUMBER(SEARCH("DEPART",UPPER('Base_Cobranzas'!$E$2:$E$1005)))+--ISNUMBER(SEARCH("DEPART",UPPER('Base_Cobranzas'!$K$2:$K$1005)))+--ISNUMBER(SEARCH("DEPART",UPPER('Base_Cobranzas'!$Q$2:$Q$1005)))+--ISNUMBER(SEARCH("DEPART",UPPER('Base_Cobranzas'!$W$2:$W$1005))))>0),--((--ISNUMBER(SEARCH("ESTACION",UPPER('Base_Cobranzas'!$E$2:$E$1005)))+--ISNUMBER(SEARCH("ESTACION",UPPER('Base_Cobranzas'!$K$2:$K$1005)))+--ISNUMBER(SEARCH("ESTACION",UPPER('Base_Cobranzas'!$Q$2:$Q$1005)))+--ISNUMBER(SEARCH("ESTACION",UPPER('Base_Cobranzas'!$W$2:$W$1005))))=0),--('Base_Cobranzas'!$AQ$2:$AQ$1005>0),'Base_Cobranzas'!$AQ$2:$AQ$1005),0) | H12: =IFERROR(SUMPRODUCT(--ISNUMBER(SEARCH($B$6,'Base_Cobranzas'!$A$2:$A$1005)),--((--ISNUMBER(SEARCH("DEPART",UPPER('Base_Cobranzas'!$E$2:$E$1005)))+--ISNUMBER(SEARCH("DEPART",UPPER('Base_Cobranzas'!$K$2:$K$1005)))+--ISNUMBER(SEARCH("DEPART",UPPER('Base_Cobranzas'!$Q$2:$Q$1005)))+--ISNUMBER(SEARCH("DEPART",UPPER('Base_Cobranzas'!$W$2:$W$1005))))>0),--((--ISNUMBER(SEARCH("ESTACION",UPPER('Base_Cobranzas'!$E$2:$E$1005)))+--ISNUMBER(SEARCH("ESTACION",UPPER('Base_Cobranzas'!$K$2:$K$1005)))+--ISNUMBER(SEARCH("ESTACION",UPPER('Base_Cobranzas'!$Q$2:$Q$1005)))+--ISNUMBER(SEARCH("ESTACION",UPPER('Base_Cobranzas'!$W$2:$W$1005))))=0),--ISNUMBER(SEARCH("PENDIENTE",UPPER(TRIM('Base_Cobranzas'!$BC$2:$BC$1005)))),'Base_Cobranzas'!$AR$2:$AR$1005),0) | I12: =IFERROR(SUMPRODUCT(--ISNUMBER(SEARCH($B$6,'Base_Cobranzas'!$A$2:$A$1005)),--((--ISNUMBER(SEARCH("DEPART",UPPER('Base_Cobranzas'!$E$2:$E$1005)))+--ISNUMBER(SEARCH("DEPART",UPPER('Base_Cobranzas'!$K$2:$K$1005)))+--ISNUMBER(SEARCH("DEPART",UPPER('Base_Cobranzas'!$Q$2:$Q$1005)))+--ISNUMBER(SEARCH("DEPART",UPPER('Base_Cobranzas'!$W$2:$W$1005))))>0),--((--ISNUMBER(SEARCH("ESTACION",UPPER('Base_Cobranzas'!$E$2:$E$1005)))+--ISNUMBER(SEARCH("ESTACION",UPPER('Base_Cobranzas'!$K$2:$K$1005)))+--ISNUMBER(SEARCH("ESTACION",UPPER('Base_Cobranzas'!$Q$2:$Q$1005)))+--ISNUMBER(SEARCH("ESTACION",UPPER('Base_Cobranzas'!$W$2:$W$1005))))=0),--ISNUMBER(SEARCH("VENCIDO",UPPER(TRIM('Base_Cobranzas'!$BC$2:$BC$1005)))),'Base_Cobranzas'!$AR$2:$AR$1005),0) | J12: =IF(C12=0,0,I12/C12) | K12: 4 | L12: 122
B13: Departamento + Estacionamiento | C13: 8852500 | D13: 31 | F13: =IF(C13=0,0,G13/C13) | G13: =IFERROR(SUMPRODUCT(--ISNUMBER(SEARCH($B$6,'Base_Cobranzas'!$A$2:$A$1005)),--((--ISNUMBER(SEARCH("DEPART",UPPER('Base_Cobranzas'!$E$2:$E$1005)))+--ISNUMBER(SEARCH("DEPART",UPPER('Base_Cobranzas'!$K$2:$K$1005)))+--ISNUMBER(SEARCH("DEPART",UPPER('Base_Cobranzas'!$Q$2:$Q$1005)))+--ISNUMBER(SEARCH("DEPART",UPPER('Base_Cobranzas'!$W$2:$W$1005))))>0),--((--ISNUMBER(SEARCH("ESTACION",UPPER('Base_Cobranzas'!$E$2:$E$1005)))+--ISNUMBER(SEARCH("ESTACION",UPPER('Base_Cobranzas'!$K$2:$K$1005)))+--ISNUMBER(SEARCH("ESTACION",UPPER('Base_Cobranzas'!$Q$2:$Q$1005)))+--ISNUMBER(SEARCH("ESTACION",UPPER('Base_Cobranzas'!$W$2:$W$1005))))>0),--('Base_Cobranzas'!$AQ$2:$AQ$1005>0),'Base_Cobranzas'!$AQ$2:$AQ$1005),0) | H13: =IFERROR(SUMPRODUCT(--ISNUMBER(SEARCH($B$6,'Base_Cobranzas'!$A$2:$A$1005)),--((--ISNUMBER(SEARCH("DEPART",UPPER('Base_Cobranzas'!$E$2:$E$1005)))+--ISNUMBER(SEARCH("DEPART",UPPER('Base_Cobranzas'!$K$2:$K$1005)))+--ISNUMBER(SEARCH("DEPART",UPPER('Base_Cobranzas'!$Q$2:$Q$1005)))+--ISNUMBER(SEARCH("DEPART",UPPER('Base_Cobranzas'!$W$2:$W$1005))))>0),--((--ISNUMBER(SEARCH("ESTACION",UPPER('Base_Cobranzas'!$E$2:$E$1005)))+--ISNUMBER(SEARCH("ESTACION",UPPER('Base_Cobranzas'!$K$2:$K$1005)))+--ISNUMBER(SEARCH("ESTACION",UPPER('Base_Cobranzas'!$Q$2:$Q$1005)))+--ISNUMBER(SEARCH("ESTACION",UPPER('Base_Cobranzas'!$W$2:$W$1005))))>0),--ISNUMBER(SEARCH("PENDIENTE",UPPER(TRIM('Base_Cobranzas'!$BC$2:$BC$1005)))),'Base_Cobranzas'!$AR$2:$AR$1005),0) | I13: =IFERROR(SUMPRODUCT(--ISNUMBER(SEARCH($B$6,'Base_Cobranzas'!$A$2:$A$1005)),--((--ISNUMBER(SEARCH("DEPART",UPPER('Base_Cobranzas'!$E$2:$E$1005)))+--ISNUMBER(SEARCH("DEPART",UPPER('Base_Cobranzas'!$K$2:$K$1005)))+--ISNUMBER(SEARCH("DEPART",UPPER('Base_Cobranzas'!$Q$2:$Q$1005)))+--ISNUMBER(SEARCH("DEPART",UPPER('Base_Cobranzas'!$W$2:$W$1005))))>0),--((--ISNUMBER(SEARCH("ESTACION",UPPER('Base_Cobranzas'!$E$2:$E$1005)))+--ISNUMBER(SEARCH("ESTACION",UPPER('Base_Cobranzas'!$K$2:$K$1005)))+--ISNUMBER(SEARCH("ESTACION",UPPER('Base_Cobranzas'!$Q$2:$Q$1005)))+--ISNUMBER(SEARCH("ESTACION",UPPER('Base_Cobranzas'!$W$2:$W$1005))))>0),--ISNUMBER(SEARCH("VENCIDO",UPPER(TRIM('Base_Cobranzas'!$BC$2:$BC$1005)))),'Base_Cobranzas'!$AR$2:$AR$1005),0) | J13: =IF(C13=0,0,I13/C13) | K13: 3 | L13: 58
B15: Estacionamientos | C15: 966400 | D15: 18 | F15: =IF(C15=0,0,G15/C15) | G15: =IFERROR(SUMPRODUCT(--ISNUMBER(SEARCH($B$6,'Base_Cobranzas'!$A$2:$A$1005)),--((--ISNUMBER(SEARCH("DEPART",UPPER('Base_Cobranzas'!$E$2:$E$1005)))+--ISNUMBER(SEARCH("DEPART",UPPER('Base_Cobranzas'!$K$2:$K$1005)))+--ISNUMBER(SEARCH("DEPART",UPPER('Base_Cobranzas'!$Q$2:$Q$1005)))+--ISNUMBER(SEARCH("DEPART",UPPER('Base_Cobranzas'!$W$2:$W$1005))))=0),--((--ISNUMBER(SEARCH("ESTACION",UPPER('Base_Cobranzas'!$E$2:$E$1005)))+--ISNUMBER(SEARCH("ESTACION",UPPER('Base_Cobranzas'!$K$2:$K$1005)))+--ISNUMBER(SEARCH("ESTACION",UPPER('Base_Cobranzas'!$Q$2:$Q$1005)))+--ISNUMBER(SEARCH("ESTACION",UPPER('Base_Cobranzas'!$W$2:$W$1005))))>0),--('Base_Cobranzas'!$AQ$2:$AQ$1005>0),'Base_Cobranzas'!$AQ$2:$AQ$1005),0) | H15: =IFERROR(SUMPRODUCT(--ISNUMBER(SEARCH($B$6,'Base_Cobranzas'!$A$2:$A$1005)),--((--ISNUMBER(SEARCH("DEPART",UPPER('Base_Cobranzas'!$E$2:$E$1005)))+--ISNUMBER(SEARCH("DEPART",UPPER('Base_Cobranzas'!$K$2:$K$1005)))+--ISNUMBER(SEARCH("DEPART",UPPER('Base_Cobranzas'!$Q$2:$Q$1005)))+--ISNUMBER(SEARCH("DEPART",UPPER('Base_Cobranzas'!$W$2:$W$1005))))=0),--((--ISNUMBER(SEARCH("ESTACION",UPPER('Base_Cobranzas'!$E$2:$E$1005)))+--ISNUMBER(SEARCH("ESTACION",UPPER('Base_Cobranzas'!$K$2:$K$1005)))+--ISNUMBER(SEARCH("ESTACION",UPPER('Base_Cobranzas'!$Q$2:$Q$1005)))+--ISNUMBER(SEARCH("ESTACION",UPPER('Base_Cobranzas'!$W$2:$W$1005))))>0),--ISNUMBER(SEARCH("PENDIENTE",UPPER(TRIM('Base_Cobranzas'!$BC$2:$BC$1005)))),'Base_Cobranzas'!$AR$2:$AR$1005),0) | I15: =IFERROR(SUMPRODUCT(--ISNUMBER(SEARCH($B$6,'Base_Cobranzas'!$A$2:$A$1005)),--((--ISNUMBER(SEARCH("DEPART",UPPER('Base_Cobranzas'!$E$2:$E$1005)))+--ISNUMBER(SEARCH("DEPART",UPPER('Base_Cobranzas'!$K$2:$K$1005)))+--ISNUMBER(SEARCH("DEPART",UPPER('Base_Cobranzas'!$Q$2:$Q$1005)))+--ISNUMBER(SEARCH("DEPART",UPPER('Base_Cobranzas'!$W$2:$W$1005))))=0),--((--ISNUMBER(SEARCH("ESTACION",UPPER('Base_Cobranzas'!$E$2:$E$1005)))+--ISNUMBER(SEARCH("ESTACION",UPPER('Base_Cobranzas'!$K$2:$K$1005)))+--ISNUMBER(SEARCH("ESTACION",UPPER('Base_Cobranzas'!$Q$2:$Q$1005)))+--ISNUMBER(SEARCH("ESTACION",UPPER('Base_Cobranzas'!$W$2:$W$1005))))>0),--ISNUMBER(SEARCH("VENCIDO",UPPER(TRIM('Base_Cobranzas'!$BC$2:$BC$1005)))),'Base_Cobranzas'!$AR$2:$AR$1005),0) | J15: =IF(C15=0,0,I15/C15) | K15: 6 | L15: 50
B17: Depositos | C17: 0 | D17: 0 | F17: =IF(C17=0,0,G17/C17) | G17: =IFERROR(SUMPRODUCT(--ISNUMBER(SEARCH($B$6,'Base_Cobranzas'!$A$2:$A$1005)),--((--ISNUMBER(SEARCH("DEPART",UPPER('Base_Cobranzas'!$E$2:$E$1005)))+--ISNUMBER(SEARCH("DEPART",UPPER('Base_Cobranzas'!$K$2:$K$1005)))+--ISNUMBER(SEARCH("DEPART",UPPER('Base_Cobranzas'!$Q$2:$Q$1005)))+--ISNUMBER(SEARCH("DEPART",UPPER('Base_Cobranzas'!$W$2:$W$1005))))=0),--((--ISNUMBER(SEARCH("ESTACION",UPPER('Base_Cobranzas'!$E$2:$E$1005)))+--ISNUMBER(SEARCH("ESTACION",UPPER('Base_Cobranzas'!$K$2:$K$1005)))+--ISNUMBER(SEARCH("ESTACION",UPPER('Base_Cobranzas'!$Q$2:$Q$1005)))+--ISNUMBER(SEARCH("ESTACION",UPPER('Base_Cobranzas'!$W$2:$W$1005))))=0),--((--ISNUMBER(SEARCH("DEPOS",UPPER('Base_Cobranzas'!$E$2:$E$1005)))+--ISNUMBER(SEARCH("DEPOS",UPPER('Base_Cobranzas'!$K$2:$K$1005)))+--ISNUMBER(SEARCH("DEPOS",UPPER('Base_Cobranzas'!$Q$2:$Q$1005)))+--ISNUMBER(SEARCH("DEPOS",UPPER('Base_Cobranzas'!$W$2:$W$1005))))>0),--('Base_Cobranzas'!$AQ$2:$AQ$1005>0),'Base_Cobranzas'!$AQ$2:$AQ$1005),0) | H17: =IFERROR(SUMPRODUCT(--ISNUMBER(SEARCH($B$6,'Base_Cobranzas'!$A$2:$A$1005)),--((--ISNUMBER(SEARCH("DEPART",UPPER('Base_Cobranzas'!$E$2:$E$1005)))+--ISNUMBER(SEARCH("DEPART",UPPER('Base_Cobranzas'!$K$2:$K$1005)))+--ISNUMBER(SEARCH("DEPART",UPPER('Base_Cobranzas'!$Q$2:$Q$1005)))+--ISNUMBER(SEARCH("DEPART",UPPER('Base_Cobranzas'!$W$2:$W$1005))))=0),--((--ISNUMBER(SEARCH("ESTACION",UPPER('Base_Cobranzas'!$E$2:$E$1005)))+--ISNUMBER(SEARCH("ESTACION",UPPER('Base_Cobranzas'!$K$2:$K$1005)))+--ISNUMBER(SEARCH("ESTACION",UPPER('Base_Cobranzas'!$Q$2:$Q$1005)))+--ISNUMBER(SEARCH("ESTACION",UPPER('Base_Cobranzas'!$W$2:$W$1005))))=0),--((--ISNUMBER(SEARCH("DEPOS",UPPER('Base_Cobranzas'!$E$2:$E$1005)))+--ISNUMBER(SEARCH("DEPOS",UPPER('Base_Cobranzas'!$K$2:$K$1005)))+--ISNUMBER(SEARCH("DEPOS",UPPER('Base_Cobranzas'!$Q$2:$Q$1005)))+--ISNUMBER(SEARCH("DEPOS",UPPER('Base_Cobranzas'!$W$2:$W$1005))))>0),--ISNUMBER(SEARCH("PENDIENTE",UPPER(TRIM('Base_Cobranzas'!$BC$2:$BC$1005)))),'Base_Cobranzas'!$AR$2:$AR$1005),0) | I17: =IFERROR(SUMPRODUCT(--ISNUMBER(SEARCH($B$6,'Base_Cobranzas'!$A$2:$A$1005)),--((--ISNUMBER(SEARCH("DEPART",UPPER('Base_Cobranzas'!$E$2:$E$1005)))+--ISNUMBER(SEARCH("DEPART",UPPER('Base_Cobranzas'!$K$2:$K$1005)))+--ISNUMBER(SEARCH("DEPART",UPPER('Base_Cobranzas'!$Q$2:$Q$1005)))+--ISNUMBER(SEARCH("DEPART",UPPER('Base_Cobranzas'!$W$2:$W$1005))))=0),--((--ISNUMBER(SEARCH("ESTACION",UPPER('Base_Cobranzas'!$E$2:$E$1005)))+--ISNUMBER(SEARCH("ESTACION",UPPER('Base_Cobranzas'!$K$2:$K$1005)))+--ISNUMBER(SEARCH("ESTACION",UPPER('Base_Cobranzas'!$Q$2:$Q$1005)))+--ISNUMBER(SEARCH("ESTACION",UPPER('Base_Cobranzas'!$W$2:$W$1005))))=0),--((--ISNUMBER(SEARCH("DEPOS",UPPER('Base_Cobranzas'!$E$2:$E$1005)))+--ISNUMBER(SEARCH("DEPOS",UPPER('Base_Cobranzas'!$K$2:$K$1005)))+--ISNUMBER(SEARCH("DEPOS",UPPER('Base_Cobranzas'!$Q$2:$Q$1005)))+--ISNUMBER(SEARCH("DEPOS",UPPER('Base_Cobranzas'!$W$2:$W$1005))))>0),--ISNUMBER(SEARCH("VENCIDO",UPPER(TRIM('Base_Cobranzas'!$BC$2:$BC$1005)))),'Base_Cobranzas'!$AR$2:$AR$1005),0) | J17: =IF(C17=0,0,I17/C17) | K17: 0 | L17: 0
B19: Local Comercial | C19: 0 | D19: 0 | F19: =IF(C19=0,0,G19/C19) | G19: =IFERROR(SUMPRODUCT(--ISNUMBER(SEARCH($B$6,'Base_Cobranzas'!$A$2:$A$1005)),--(((--ISNUMBER(SEARCH("LOCAL",UPPER('Base_Cobranzas'!$E$2:$E$1005)))+--ISNUMBER(SEARCH("LOCAL",UPPER('Base_Cobranzas'!$K$2:$K$1005)))+--ISNUMBER(SEARCH("LOCAL",UPPER('Base_Cobranzas'!$Q$2:$Q$1005)))+--ISNUMBER(SEARCH("LOCAL",UPPER('Base_Cobranzas'!$W$2:$W$1005))))+(--ISNUMBER(SEARCH("COMERCIAL",UPPER('Base_Cobranzas'!$E$2:$E$1005)))+--ISNUMBER(SEARCH("COMERCIAL",UPPER('Base_Cobranzas'!$K$2:$K$1005)))+--ISNUMBER(SEARCH("COMERCIAL",UPPER('Base_Cobranzas'!$Q$2:$Q$1005)))+--ISNUMBER(SEARCH("COMERCIAL",UPPER('Base_Cobranzas'!$W$2:$W$1005)))))>0),--('Base_Cobranzas'!$AQ$2:$AQ$1005>0),'Base_Cobranzas'!$AQ$2:$AQ$1005),0) | H19: =IFERROR(SUMPRODUCT(--ISNUMBER(SEARCH($B$6,'Base_Cobranzas'!$A$2:$A$1005)),--(((--ISNUMBER(SEARCH("LOCAL",UPPER('Base_Cobranzas'!$E$2:$E$1005)))+--ISNUMBER(SEARCH("LOCAL",UPPER('Base_Cobranzas'!$K$2:$K$1005)))+--ISNUMBER(SEARCH("LOCAL",UPPER('Base_Cobranzas'!$Q$2:$Q$1005)))+--ISNUMBER(SEARCH("LOCAL",UPPER('Base_Cobranzas'!$W$2:$W$1005))))+(--ISNUMBER(SEARCH("COMERCIAL",UPPER('Base_Cobranzas'!$E$2:$E$1005)))+--ISNUMBER(SEARCH("COMERCIAL",UPPER('Base_Cobranzas'!$K$2:$K$1005)))+--ISNUMBER(SEARCH("COMERCIAL",UPPER('Base_Cobranzas'!$Q$2:$Q$1005)))+--ISNUMBER(SEARCH("COMERCIAL",UPPER('Base_Cobranzas'!$W$2:$W$1005)))))>0),--ISNUMBER(SEARCH("PENDIENTE",UPPER(TRIM('Base_Cobranzas'!$BC$2:$BC$1005)))),'Base_Cobranzas'!$AR$2:$AR$1005),0) | I19: =IFERROR(SUMPRODUCT(--ISNUMBER(SEARCH($B$6,'Base_Cobranzas'!$A$2:$A$1005)),--(((--ISNUMBER(SEARCH("LOCAL",UPPER('Base_Cobranzas'!$E$2:$E$1005)))+--ISNUMBER(SEARCH("LOCAL",UPPER('Base_Cobranzas'!$K$2:$K$1005)))+--ISNUMBER(SEARCH("LOCAL",UPPER('Base_Cobranzas'!$Q$2:$Q$1005)))+--ISNUMBER(SEARCH("LOCAL",UPPER('Base_Cobranzas'!$W$2:$W$1005))))+(--ISNUMBER(SEARCH("COMERCIAL",UPPER('Base_Cobranzas'!$E$2:$E$1005)))+--ISNUMBER(SEARCH("COMERCIAL",UPPER('Base_Cobranzas'!$K$2:$K$1005)))+--ISNUMBER(SEARCH("COMERCIAL",UPPER('Base_Cobranzas'!$Q$2:$Q$1005)))+--ISNUMBER(SEARCH("COMERCIAL",UPPER('Base_Cobranzas'!$W$2:$W$1005)))))>0),--ISNUMBER(SEARCH("VENCIDO",UPPER(TRIM('Base_Cobranzas'!$BC$2:$BC$1005)))),'Base_Cobranzas'!$AR$2:$AR$1005),0) | J19: =IF(C19=0,0,I19/C19) | K19: 0 | L19: 0
A21: =+IF(ROUND(C21,0)=ROUND(G21+H21+I21,0),"OK","REVISAR") | B21: Total | C21: 26220000 | D21: 80 | F21: =IF(C21=0,0,G21/C21) | G21: =G11+G15+G17+G19 | H21: =H11+H15+H17+H19 | I21: =I11+I15+I17+I19 | J21: =IF(C21=0,0,I21/C21) | K21: 12 | L21: 74
B31: COBRANZA REAL
B33: Tipo de Credito | C33: 2024 | D33: 2025 | E33: 46023 | F33: 46054 | G33: 46082 | H33: 46113 | I33: 46143 | J33: 46174 | K33: 46204 | L33: 46235 | M33: 46266 | N33: Total
B34: Crédito Directo | C34: =IFERROR(SUMPRODUCT(--ISNUMBER(SEARCH($B$6,'Base_Cobranzas'!$A$2:$A$1005)),--('Base_Cobranzas'!$AJ$2:$AJ$1005>=IF(C$33<3000,DATE(C$33,1,1),C$33)),--('Base_Cobranzas'!$AJ$2:$AJ$1005<IF(C$33<3000,DATE(C$33+1,1,1),EDATE(C$33,1))),--ISNUMBER(SEARCH(IF(ISNUMBER(SEARCH("DIRECTO",UPPER($B34))),"DIRECTO",IF(ISNUMBER(SEARCH("HIPOT",UPPER($B34))),"HIPOT",IF(ISNUMBER(SEARCH("AHORRO",UPPER($B34))),"AHORRO",UPPER($B34)))),UPPER('Base_Cobranzas'!$AT$2:$AT$1005))),--('Base_Cobranzas'!$AQ$2:$AQ$1005>0),'Base_Cobranzas'!$AQ$2:$AQ$1005),0) | D34: =IFERROR(SUMPRODUCT(--ISNUMBER(SEARCH($B$6,'Base_Cobranzas'!$A$2:$A$1005)),--('Base_Cobranzas'!$AJ$2:$AJ$1005>=IF(D$33<3000,DATE(D$33,1,1),D$33)),--('Base_Cobranzas'!$AJ$2:$AJ$1005<IF(D$33<3000,DATE(D$33+1,1,1),EDATE(D$33,1))),--ISNUMBER(SEARCH(IF(ISNUMBER(SEARCH("DIRECTO",UPPER($B34))),"DIRECTO",IF(ISNUMBER(SEARCH("HIPOT",UPPER($B34))),"HIPOT",IF(ISNUMBER(SEARCH("AHORRO",UPPER($B34))),"AHORRO",UPPER($B34)))),UPPER('Base_Cobranzas'!$AT$2:$AT$1005))),--('Base_Cobranzas'!$AQ$2:$AQ$1005>0),'Base_Cobranzas'!$AQ$2:$AQ$1005),0) | E34: =IFERROR(SUMPRODUCT(--ISNUMBER(SEARCH($B$6,'Base_Cobranzas'!$A$2:$A$1005)),--('Base_Cobranzas'!$AJ$2:$AJ$1005>=IF(E$33<3000,DATE(E$33,1,1),E$33)),--('Base_Cobranzas'!$AJ$2:$AJ$1005<IF(E$33<3000,DATE(E$33+1,1,1),EDATE(E$33,1))),--ISNUMBER(SEARCH(IF(ISNUMBER(SEARCH("DIRECTO",UPPER($B34))),"DIRECTO",IF(ISNUMBER(SEARCH("HIPOT",UPPER($B34))),"HIPOT",IF(ISNUMBER(SEARCH("AHORRO",UPPER($B34))),"AHORRO",UPPER($B34)))),UPPER('Base_Cobranzas'!$AT$2:$AT$1005))),--('Base_Cobranzas'!$AQ$2:$AQ$1005>0),'Base_Cobranzas'!$AQ$2:$AQ$1005),0) | F34: =IFERROR(SUMPRODUCT(--ISNUMBER(SEARCH($B$6,'Base_Cobranzas'!$A$2:$A$1005)),--('Base_Cobranzas'!$AJ$2:$AJ$1005>=IF(F$33<3000,DATE(F$33,1,1),F$33)),--('Base_Cobranzas'!$AJ$2:$AJ$1005<IF(F$33<3000,DATE(F$33+1,1,1),EDATE(F$33,1))),--ISNUMBER(SEARCH(IF(ISNUMBER(SEARCH("DIRECTO",UPPER($B34))),"DIRECTO",IF(ISNUMBER(SEARCH("HIPOT",UPPER($B34))),"HIPOT",IF(ISNUMBER(SEARCH("AHORRO",UPPER($B34))),"AHORRO",UPPER($B34)))),UPPER('Base_Cobranzas'!$AT$2:$AT$1005))),--('Base_Cobranzas'!$AQ$2:$AQ$1005>0),'Base_Cobranzas'!$AQ$2:$AQ$1005),0) | G34: =IFERROR(SUMPRODUCT(--ISNUMBER(SEARCH($B$6,'Base_Cobranzas'!$A$2:$A$1005)),--('Base_Cobranzas'!$AJ$2:$AJ$1005>=IF(G$33<3000,DATE(G$33,1,1),G$33)),--('Base_Cobranzas'!$AJ$2:$AJ$1005<IF(G$33<3000,DATE(G$33+1,1,1),EDATE(G$33,1))),--ISNUMBER(SEARCH(IF(ISNUMBER(SEARCH("DIRECTO",UPPER($B34))),"DIRECTO",IF(ISNUMBER(SEARCH("HIPOT",UPPER($B34))),"HIPOT",IF(ISNUMBER(SEARCH("AHORRO",UPPER($B34))),"AHORRO",UPPER($B34)))),UPPER('Base_Cobranzas'!$AT$2:$AT$1005))),--('Base_Cobranzas'!$AQ$2:$AQ$1005>0),'Base_Cobranzas'!$AQ$2:$AQ$1005),0) | H34: =IFERROR(SUMPRODUCT(--ISNUMBER(SEARCH($B$6,'Base_Cobranzas'!$A$2:$A$1005)),--('Base_Cobranzas'!$AJ$2:$AJ$1005>=IF(H$33<3000,DATE(H$33,1,1),H$33)),--('Base_Cobranzas'!$AJ$2:$AJ$1005<IF(H$33<3000,DATE(H$33+1,1,1),EDATE(H$33,1))),--ISNUMBER(SEARCH(IF(ISNUMBER(SEARCH("DIRECTO",UPPER($B34))),"DIRECTO",IF(ISNUMBER(SEARCH("HIPOT",UPPER($B34))),"HIPOT",IF(ISNUMBER(SEARCH("AHORRO",UPPER($B34))),"AHORRO",UPPER($B34)))),UPPER('Base_Cobranzas'!$AT$2:$AT$1005))),--('Base_Cobranzas'!$AQ$2:$AQ$1005>0),'Base_Cobranzas'!$AQ$2:$AQ$1005),0) | I34: =IFERROR(SUMPRODUCT(--ISNUMBER(SEARCH($B$6,'Base_Cobranzas'!$A$2:$A$1005)),--('Base_Cobranzas'!$AJ$2:$AJ$1005>=IF(I$33<3000,DATE(I$33,1,1),I$33)),--('Base_Cobranzas'!$AJ$2:$AJ$1005<IF(I$33<3000,DATE(I$33+1,1,1),EDATE(I$33,1))),--ISNUMBER(SEARCH(IF(ISNUMBER(SEARCH("DIRECTO",UPPER($B34))),"DIRECTO",IF(ISNUMBER(SEARCH("HIPOT",UPPER($B34))),"HIPOT",IF(ISNUMBER(SEARCH("AHORRO",UPPER($B34))),"AHORRO",UPPER($B34)))),UPPER('Base_Cobranzas'!$AT$2:$AT$1005))),--('Base_Cobranzas'!$AQ$2:$AQ$1005>0),'Base_Cobranzas'!$AQ$2:$AQ$1005),0) | J34: =IFERROR(SUMPRODUCT(--ISNUMBER(SEARCH($B$6,'Base_Cobranzas'!$A$2:$A$1005)),--('Base_Cobranzas'!$AJ$2:$AJ$1005>=IF(J$33<3000,DATE(J$33,1,1),J$33)),--('Base_Cobranzas'!$AJ$2:$AJ$1005<IF(J$33<3000,DATE(J$33+1,1,1),EDATE(J$33,1))),--ISNUMBER(SEARCH(IF(ISNUMBER(SEARCH("DIRECTO",UPPER($B34))),"DIRECTO",IF(ISNUMBER(SEARCH("HIPOT",UPPER($B34))),"HIPOT",IF(ISNUMBER(SEARCH("AHORRO",UPPER($B34))),"AHORRO",UPPER($B34)))),UPPER('Base_Cobranzas'!$AT$2:$AT$1005))),--('Base_Cobranzas'!$AQ$2:$AQ$1005>0),'Base_Cobranzas'!$AQ$2:$AQ$1005),0) | ... M34: =IFERROR(SUMPRODUCT(--ISNUMBER(SEARCH($B$6,'Base_Cobranzas'!$A$2:$A$1005)),--('Base_Cobranzas'!$AJ$2:$AJ$1005>=IF(M$33<3000,DATE(M$33,1,1),M$33)),--('Base_Cobranzas'!$AJ$2:$AJ$1005<IF(M$33<3000,DATE(M$33+1,1,1),EDATE(M$33,1))),--ISNUMBER(SEARCH(IF(ISNUMBER(SEARCH("DIRECTO",UPPER($B34))),"DIRECTO",IF(ISNUMBER(SEARCH("HIPOT",UPPER($B34))),"HIPOT",IF(ISNUMBER(SEARCH("AHORRO",UPPER($B34))),"AHORRO",UPPER($B34)))),UPPER('Base_Cobranzas'!$AT$2:$AT$1005))),--('Base_Cobranzas'!$AQ$2:$AQ$1005>0),'Base_Cobranzas'!$AQ$2:$AQ$1005),0) | N34: =SUM(C34:M34)
